[Thu Apr 17 09:38:58 2014] [error] Login successful for user "admin".
[Thu Apr 17 09:40:24 2014] [error] Logging out user "admin".
[Thu Apr 17 09:40:39 2014] [error] Login successful for user "admin".
[Thu Apr 17 09:40:44 2014] [error] Logging out user "admin".
[Thu Apr 17 09:41:13 2014] [error] Login successful for user "admin".
[Thu Apr 17 09:41:24 2014] [error] Iniciado Inst\xc3\xa2ncia: "dfire_test_1"
[Thu Apr 17 09:44:21 2014] [error] Not Found: No more floating ips available. (HTTP 404) (Request-ID: req-b6a661ed-6991-447b-b1ad-17807186ea69)
[Thu Apr 17 09:44:21 2014] [error] Traceback (most recent call last):
[Thu Apr 17 09:44:21 2014] [error]   File "/usr/share/openstack-dashboard/openstack_dashboard/wsgi/../../openstack_dashboard/dashboards/project/instances/tables.py", line 386, in single
[Thu Apr 17 09:44:21 2014] [error]     fip = api.network.tenant_floating_ip_allocate(request)
[Thu Apr 17 09:44:21 2014] [error]   File "/usr/share/openstack-dashboard/openstack_dashboard/wsgi/../../openstack_dashboard/api/network.py", line 60, in tenant_floating_ip_allocate
[Thu Apr 17 09:44:21 2014] [error]     return NetworkClient(request).floating_ips.allocate(pool)
[Thu Apr 17 09:44:21 2014] [error]   File "/usr/share/openstack-dashboard/openstack_dashboard/wsgi/../../openstack_dashboard/api/nova.py", line 331, in allocate
[Thu Apr 17 09:44:21 2014] [error]     return FloatingIp(self.client.floating_ips.create(pool=pool))
[Thu Apr 17 09:44:21 2014] [error]   File "/usr/lib/python2.7/dist-packages/novaclient/v1_1/floating_ips.py", line 41, in create
[Thu Apr 17 09:44:21 2014] [error]     return self._create("/os-floating-ips", {'pool': pool}, "floating_ip")
[Thu Apr 17 09:44:21 2014] [error]   File "/usr/lib/python2.7/dist-packages/novaclient/base.py", line 145, in _create
[Thu Apr 17 09:44:21 2014] [error]     _resp, body = self.api.client.post(url, body=body)
[Thu Apr 17 09:44:21 2014] [error]   File "/usr/lib/python2.7/dist-packages/novaclient/client.py", line 232, in post
[Thu Apr 17 09:44:21 2014] [error]     return self._cs_request(url, 'POST', **kwargs)
[Thu Apr 17 09:44:21 2014] [error]   File "/usr/lib/python2.7/dist-packages/novaclient/client.py", line 213, in _cs_request
[Thu Apr 17 09:44:21 2014] [error]     **kwargs)
[Thu Apr 17 09:44:21 2014] [error]   File "/usr/lib/python2.7/dist-packages/novaclient/client.py", line 195, in _time_request
[Thu Apr 17 09:44:21 2014] [error]     resp, body = self.request(url, method, **kwargs)
[Thu Apr 17 09:44:21 2014] [error]   File "/usr/lib/python2.7/dist-packages/novaclient/client.py", line 189, in request
[Thu Apr 17 09:44:21 2014] [error]     raise exceptions.from_response(resp, body, url, method)
[Thu Apr 17 09:44:21 2014] [error] NotFound: No more floating ips available. (HTTP 404) (Request-ID: req-b6a661ed-6991-447b-b1ad-17807186ea69)
[Thu Apr 17 10:13:02 2014] [notice] Apache/2.2.22 (Ubuntu) configured -- resuming normal operations
[Thu Apr 17 10:13:04 2014] [notice] caught SIGTERM, shutting down
[Thu Apr 17 10:13:05 2014] [warn] mod_wsgi: Compiled for Python/2.7.2+.
[Thu Apr 17 10:13:05 2014] [warn] mod_wsgi: Runtime using Python/2.7.3.
[Thu Apr 17 10:13:05 2014] [notice] Apache/2.2.22 (Ubuntu) mod_wsgi/3.3 Python/2.7.3 configured -- resuming normal operations
[Thu Apr 17 10:13:10 2014] [notice] SIGUSR1 received.  Doing graceful restart
apache2: Could not reliably determine the server's fully qualified domain name, using 137.43.154.99 for ServerName
[Thu Apr 17 10:13:10 2014] [warn] mod_wsgi: Compiled for Python/2.7.2+.
[Thu Apr 17 10:13:10 2014] [warn] mod_wsgi: Runtime using Python/2.7.3.
[Thu Apr 17 10:13:10 2014] [notice] Apache/2.2.22 (Ubuntu) mod_wsgi/3.3 Python/2.7.3 configured -- resuming normal operations
[Thu Apr 17 10:13:13 2014] [notice] SIGUSR1 received.  Doing graceful restart
apache2: Could not reliably determine the server's fully qualified domain name, using 137.43.154.99 for ServerName
[Thu Apr 17 10:13:13 2014] [warn] mod_wsgi: Compiled for Python/2.7.2+.
[Thu Apr 17 10:13:13 2014] [warn] mod_wsgi: Runtime using Python/2.7.3.
[Thu Apr 17 10:13:13 2014] [notice] Apache/2.2.22 (Ubuntu) mod_wsgi/3.3 Python/2.7.3 configured -- resuming normal operations
[Thu Apr 17 10:13:22 2014] [notice] SIGUSR1 received.  Doing graceful restart
apache2: Could not reliably determine the server's fully qualified domain name, using 137.43.154.99 for ServerName
[Thu Apr 17 10:13:22 2014] [warn] mod_wsgi: Compiled for Python/2.7.2+.
[Thu Apr 17 10:13:22 2014] [warn] mod_wsgi: Runtime using Python/2.7.3.
[Thu Apr 17 10:13:22 2014] [notice] Apache/2.2.22 (Ubuntu) mod_wsgi/3.3 Python/2.7.3 configured -- resuming normal operations
[Thu Apr 17 10:13:23 2014] [notice] SIGUSR1 received.  Doing graceful restart
apache2: Could not reliably determine the server's fully qualified domain name, using 137.43.154.99 for ServerName
[Thu Apr 17 10:13:23 2014] [warn] mod_wsgi: Compiled for Python/2.7.2+.
[Thu Apr 17 10:13:23 2014] [warn] mod_wsgi: Runtime using Python/2.7.3.
[Thu Apr 17 10:13:23 2014] [notice] Apache/2.2.22 (Ubuntu) mod_wsgi/3.3 Python/2.7.3 configured -- resuming normal operations
[Thu Apr 17 10:14:48 2014] [error] Logging out user "admin".
[Thu Apr 17 10:14:59 2014] [error] Login successful for user "glance".
[Thu Apr 17 10:15:37 2014] [error] Logging out user "glance".
[Thu Apr 17 10:17:50 2014] [notice] caught SIGTERM, shutting down
[Thu Apr 17 10:17:51 2014] [warn] mod_wsgi: Compiled for Python/2.7.2+.
[Thu Apr 17 10:17:51 2014] [warn] mod_wsgi: Runtime using Python/2.7.3.
[Thu Apr 17 10:17:51 2014] [notice] Apache/2.2.22 (Ubuntu) mod_wsgi/3.3 Python/2.7.3 configured -- resuming normal operations
[Thu Apr 17 10:45:19 2014] [error] [client 137.43.154.74] File does not exist: /var/www/favicon.ico
[Thu Apr 17 10:45:19 2014] [error] [client 137.43.154.74] File does not exist: /var/www/favicon.ico
[Thu Apr 17 11:31:49 2014] [error] Login successful for user "admin".
[Thu Apr 17 11:32:19 2014] [error] Not Found: No more floating ips available. (HTTP 404) (Request-ID: req-0e401c49-cb3f-42a9-90e0-cdeacfd604d1)
[Thu Apr 17 11:32:19 2014] [error] Traceback (most recent call last):
[Thu Apr 17 11:32:19 2014] [error]   File "/usr/share/openstack-dashboard/openstack_dashboard/wsgi/../../openstack_dashboard/dashboards/project/instances/tables.py", line 386, in single
[Thu Apr 17 11:32:19 2014] [error]     fip = api.network.tenant_floating_ip_allocate(request)
[Thu Apr 17 11:32:19 2014] [error]   File "/usr/share/openstack-dashboard/openstack_dashboard/wsgi/../../openstack_dashboard/api/network.py", line 60, in tenant_floating_ip_allocate
[Thu Apr 17 11:32:19 2014] [error]     return NetworkClient(request).floating_ips.allocate(pool)
[Thu Apr 17 11:32:19 2014] [error]   File "/usr/share/openstack-dashboard/openstack_dashboard/wsgi/../../openstack_dashboard/api/nova.py", line 331, in allocate
[Thu Apr 17 11:32:19 2014] [error]     return FloatingIp(self.client.floating_ips.create(pool=pool))
[Thu Apr 17 11:32:19 2014] [error]   File "/usr/lib/python2.7/dist-packages/novaclient/v1_1/floating_ips.py", line 41, in create
[Thu Apr 17 11:32:19 2014] [error]     return self._create("/os-floating-ips", {'pool': pool}, "floating_ip")
[Thu Apr 17 11:32:19 2014] [error]   File "/usr/lib/python2.7/dist-packages/novaclient/base.py", line 145, in _create
[Thu Apr 17 11:32:19 2014] [error]     _resp, body = self.api.client.post(url, body=body)
[Thu Apr 17 11:32:19 2014] [error]   File "/usr/lib/python2.7/dist-packages/novaclient/client.py", line 232, in post
[Thu Apr 17 11:32:19 2014] [error]     return self._cs_request(url, 'POST', **kwargs)
[Thu Apr 17 11:32:19 2014] [error]   File "/usr/lib/python2.7/dist-packages/novaclient/client.py", line 213, in _cs_request
[Thu Apr 17 11:32:19 2014] [error]     **kwargs)
[Thu Apr 17 11:32:19 2014] [error]   File "/usr/lib/python2.7/dist-packages/novaclient/client.py", line 195, in _time_request
[Thu Apr 17 11:32:19 2014] [error]     resp, body = self.request(url, method, **kwargs)
[Thu Apr 17 11:32:19 2014] [error]   File "/usr/lib/python2.7/dist-packages/novaclient/client.py", line 189, in request
[Thu Apr 17 11:32:19 2014] [error]     raise exceptions.from_response(resp, body, url, method)
[Thu Apr 17 11:32:19 2014] [error] NotFound: No more floating ips available. (HTTP 404) (Request-ID: req-0e401c49-cb3f-42a9-90e0-cdeacfd604d1)
[Thu Apr 17 11:57:16 2014] [error] Logging out user "admin".
[Thu Apr 17 12:31:17 2014] [error] [client 137.43.154.74] File does not exist: /var/www/auth
[Thu Apr 17 13:03:10 2014] [error] Login successful for user "admin".
[Thu Apr 17 13:06:53 2014] [error] Started Instance: "dfire_test_1"
[Thu Apr 17 13:35:01 2014] [error] Started Instance: "dfire_test_1"
[Thu Apr 17 13:35:12 2014] [error] Not Found: No more floating ips available. (HTTP 404) (Request-ID: req-00855ea3-a223-438e-9dd6-afb0dae8c374)
[Thu Apr 17 13:35:12 2014] [error] Traceback (most recent call last):
[Thu Apr 17 13:35:12 2014] [error]   File "/usr/share/openstack-dashboard/openstack_dashboard/wsgi/../../openstack_dashboard/dashboards/project/instances/tables.py", line 386, in single
[Thu Apr 17 13:35:12 2014] [error]     fip = api.network.tenant_floating_ip_allocate(request)
[Thu Apr 17 13:35:12 2014] [error]   File "/usr/share/openstack-dashboard/openstack_dashboard/wsgi/../../openstack_dashboard/api/network.py", line 60, in tenant_floating_ip_allocate
[Thu Apr 17 13:35:12 2014] [error]     return NetworkClient(request).floating_ips.allocate(pool)
[Thu Apr 17 13:35:12 2014] [error]   File "/usr/share/openstack-dashboard/openstack_dashboard/wsgi/../../openstack_dashboard/api/nova.py", line 331, in allocate
[Thu Apr 17 13:35:12 2014] [error]     return FloatingIp(self.client.floating_ips.create(pool=pool))
[Thu Apr 17 13:35:12 2014] [error]   File "/usr/lib/python2.7/dist-packages/novaclient/v1_1/floating_ips.py", line 41, in create
[Thu Apr 17 13:35:12 2014] [error]     return self._create("/os-floating-ips", {'pool': pool}, "floating_ip")
[Thu Apr 17 13:35:12 2014] [error]   File "/usr/lib/python2.7/dist-packages/novaclient/base.py", line 145, in _create
[Thu Apr 17 13:35:12 2014] [error]     _resp, body = self.api.client.post(url, body=body)
[Thu Apr 17 13:35:12 2014] [error]   File "/usr/lib/python2.7/dist-packages/novaclient/client.py", line 232, in post
[Thu Apr 17 13:35:12 2014] [error]     return self._cs_request(url, 'POST', **kwargs)
[Thu Apr 17 13:35:12 2014] [error]   File "/usr/lib/python2.7/dist-packages/novaclient/client.py", line 213, in _cs_request
[Thu Apr 17 13:35:12 2014] [error]     **kwargs)
[Thu Apr 17 13:35:12 2014] [error]   File "/usr/lib/python2.7/dist-packages/novaclient/client.py", line 195, in _time_request
[Thu Apr 17 13:35:12 2014] [error]     resp, body = self.request(url, method, **kwargs)
[Thu Apr 17 13:35:12 2014] [error]   File "/usr/lib/python2.7/dist-packages/novaclient/client.py", line 189, in request
[Thu Apr 17 13:35:12 2014] [error]     raise exceptions.from_response(resp, body, url, method)
[Thu Apr 17 13:35:12 2014] [error] NotFound: No more floating ips available. (HTTP 404) (Request-ID: req-00855ea3-a223-438e-9dd6-afb0dae8c374)
[Thu Apr 17 13:39:30 2014] [error] Soft Rebooted Instance: "dfire_test_1"
[Thu Apr 17 13:41:14 2014] [error] Scheduled termination of Instance: "dfire_test_1"
[Thu Apr 17 13:42:49 2014] [error] Not Found: No more floating ips available. (HTTP 404) (Request-ID: req-6adfce06-c7bf-4ba8-aa79-1c29ab6740cb)
[Thu Apr 17 13:42:49 2014] [error] Traceback (most recent call last):
[Thu Apr 17 13:42:49 2014] [error]   File "/usr/share/openstack-dashboard/openstack_dashboard/wsgi/../../openstack_dashboard/dashboards/project/instances/tables.py", line 386, in single
[Thu Apr 17 13:42:49 2014] [error]     fip = api.network.tenant_floating_ip_allocate(request)
[Thu Apr 17 13:42:49 2014] [error]   File "/usr/share/openstack-dashboard/openstack_dashboard/wsgi/../../openstack_dashboard/api/network.py", line 60, in tenant_floating_ip_allocate
[Thu Apr 17 13:42:49 2014] [error]     return NetworkClient(request).floating_ips.allocate(pool)
[Thu Apr 17 13:42:49 2014] [error]   File "/usr/share/openstack-dashboard/openstack_dashboard/wsgi/../../openstack_dashboard/api/nova.py", line 331, in allocate
[Thu Apr 17 13:42:49 2014] [error]     return FloatingIp(self.client.floating_ips.create(pool=pool))
[Thu Apr 17 13:42:49 2014] [error]   File "/usr/lib/python2.7/dist-packages/novaclient/v1_1/floating_ips.py", line 41, in create
[Thu Apr 17 13:42:49 2014] [error]     return self._create("/os-floating-ips", {'pool': pool}, "floating_ip")
[Thu Apr 17 13:42:49 2014] [error]   File "/usr/lib/python2.7/dist-packages/novaclient/base.py", line 145, in _create
[Thu Apr 17 13:42:49 2014] [error]     _resp, body = self.api.client.post(url, body=body)
[Thu Apr 17 13:42:49 2014] [error]   File "/usr/lib/python2.7/dist-packages/novaclient/client.py", line 232, in post
[Thu Apr 17 13:42:49 2014] [error]     return self._cs_request(url, 'POST', **kwargs)
[Thu Apr 17 13:42:49 2014] [error]   File "/usr/lib/python2.7/dist-packages/novaclient/client.py", line 213, in _cs_request
[Thu Apr 17 13:42:49 2014] [error]     **kwargs)
[Thu Apr 17 13:42:49 2014] [error]   File "/usr/lib/python2.7/dist-packages/novaclient/client.py", line 195, in _time_request
[Thu Apr 17 13:42:49 2014] [error]     resp, body = self.request(url, method, **kwargs)
[Thu Apr 17 13:42:49 2014] [error]   File "/usr/lib/python2.7/dist-packages/novaclient/client.py", line 189, in request
[Thu Apr 17 13:42:49 2014] [error]     raise exceptions.from_response(resp, body, url, method)
[Thu Apr 17 13:42:49 2014] [error] NotFound: No more floating ips available. (HTTP 404) (Request-ID: req-6adfce06-c7bf-4ba8-aa79-1c29ab6740cb)
[Thu Apr 17 13:45:46 2014] [error] Not Found: No more floating ips available. (HTTP 404) (Request-ID: req-a4da974e-8f10-4f1e-a322-3093fa41ccac)
[Thu Apr 17 13:45:46 2014] [error] Traceback (most recent call last):
[Thu Apr 17 13:45:46 2014] [error]   File "/usr/share/openstack-dashboard/openstack_dashboard/wsgi/../../openstack_dashboard/dashboards/project/instances/tables.py", line 386, in single
[Thu Apr 17 13:45:46 2014] [error]     fip = api.network.tenant_floating_ip_allocate(request)
[Thu Apr 17 13:45:46 2014] [error]   File "/usr/share/openstack-dashboard/openstack_dashboard/wsgi/../../openstack_dashboard/api/network.py", line 60, in tenant_floating_ip_allocate
[Thu Apr 17 13:45:46 2014] [error]     return NetworkClient(request).floating_ips.allocate(pool)
[Thu Apr 17 13:45:46 2014] [error]   File "/usr/share/openstack-dashboard/openstack_dashboard/wsgi/../../openstack_dashboard/api/nova.py", line 331, in allocate
[Thu Apr 17 13:45:46 2014] [error]     return FloatingIp(self.client.floating_ips.create(pool=pool))
[Thu Apr 17 13:45:46 2014] [error]   File "/usr/lib/python2.7/dist-packages/novaclient/v1_1/floating_ips.py", line 41, in create
[Thu Apr 17 13:45:46 2014] [error]     return self._create("/os-floating-ips", {'pool': pool}, "floating_ip")
[Thu Apr 17 13:45:46 2014] [error]   File "/usr/lib/python2.7/dist-packages/novaclient/base.py", line 145, in _create
[Thu Apr 17 13:45:46 2014] [error]     _resp, body = self.api.client.post(url, body=body)
[Thu Apr 17 13:45:46 2014] [error]   File "/usr/lib/python2.7/dist-packages/novaclient/client.py", line 232, in post
[Thu Apr 17 13:45:46 2014] [error]     return self._cs_request(url, 'POST', **kwargs)
[Thu Apr 17 13:45:46 2014] [error]   File "/usr/lib/python2.7/dist-packages/novaclient/client.py", line 213, in _cs_request
[Thu Apr 17 13:45:46 2014] [error]     **kwargs)
[Thu Apr 17 13:45:46 2014] [error]   File "/usr/lib/python2.7/dist-packages/novaclient/client.py", line 195, in _time_request
[Thu Apr 17 13:45:46 2014] [error]     resp, body = self.request(url, method, **kwargs)
[Thu Apr 17 13:45:46 2014] [error]   File "/usr/lib/python2.7/dist-packages/novaclient/client.py", line 189, in request
[Thu Apr 17 13:45:46 2014] [error]     raise exceptions.from_response(resp, body, url, method)
[Thu Apr 17 13:45:46 2014] [error] NotFound: No more floating ips available. (HTTP 404) (Request-ID: req-a4da974e-8f10-4f1e-a322-3093fa41ccac)
[Thu Apr 17 13:49:10 2014] [error] Not Found: No more floating ips available. (HTTP 404) (Request-ID: req-8b5e2792-8205-4bcd-b66c-bb5d92f149a6)
[Thu Apr 17 13:49:10 2014] [error] Traceback (most recent call last):
[Thu Apr 17 13:49:10 2014] [error]   File "/usr/share/openstack-dashboard/openstack_dashboard/wsgi/../../openstack_dashboard/dashboards/project/instances/tables.py", line 386, in single
[Thu Apr 17 13:49:10 2014] [error]     fip = api.network.tenant_floating_ip_allocate(request)
[Thu Apr 17 13:49:10 2014] [error]   File "/usr/share/openstack-dashboard/openstack_dashboard/wsgi/../../openstack_dashboard/api/network.py", line 60, in tenant_floating_ip_allocate
[Thu Apr 17 13:49:10 2014] [error]     return NetworkClient(request).floating_ips.allocate(pool)
[Thu Apr 17 13:49:10 2014] [error]   File "/usr/share/openstack-dashboard/openstack_dashboard/wsgi/../../openstack_dashboard/api/nova.py", line 331, in allocate
[Thu Apr 17 13:49:10 2014] [error]     return FloatingIp(self.client.floating_ips.create(pool=pool))
[Thu Apr 17 13:49:10 2014] [error]   File "/usr/lib/python2.7/dist-packages/novaclient/v1_1/floating_ips.py", line 41, in create
[Thu Apr 17 13:49:10 2014] [error]     return self._create("/os-floating-ips", {'pool': pool}, "floating_ip")
[Thu Apr 17 13:49:10 2014] [error]   File "/usr/lib/python2.7/dist-packages/novaclient/base.py", line 145, in _create
[Thu Apr 17 13:49:10 2014] [error]     _resp, body = self.api.client.post(url, body=body)
[Thu Apr 17 13:49:10 2014] [error]   File "/usr/lib/python2.7/dist-packages/novaclient/client.py", line 232, in post
[Thu Apr 17 13:49:10 2014] [error]     return self._cs_request(url, 'POST', **kwargs)
[Thu Apr 17 13:49:10 2014] [error]   File "/usr/lib/python2.7/dist-packages/novaclient/client.py", line 213, in _cs_request
[Thu Apr 17 13:49:10 2014] [error]     **kwargs)
[Thu Apr 17 13:49:10 2014] [error]   File "/usr/lib/python2.7/dist-packages/novaclient/client.py", line 195, in _time_request
[Thu Apr 17 13:49:10 2014] [error]     resp, body = self.request(url, method, **kwargs)
[Thu Apr 17 13:49:10 2014] [error]   File "/usr/lib/python2.7/dist-packages/novaclient/client.py", line 189, in request
[Thu Apr 17 13:49:10 2014] [error]     raise exceptions.from_response(resp, body, url, method)
[Thu Apr 17 13:49:10 2014] [error] NotFound: No more floating ips available. (HTTP 404) (Request-ID: req-8b5e2792-8205-4bcd-b66c-bb5d92f149a6)
[Thu Apr 17 13:50:08 2014] [error] Not Found: No more floating ips available. (HTTP 404) (Request-ID: req-2eb0fb08-57bd-4b99-a947-df802e5372d4)
[Thu Apr 17 13:50:08 2014] [error] Traceback (most recent call last):
[Thu Apr 17 13:50:08 2014] [error]   File "/usr/share/openstack-dashboard/openstack_dashboard/wsgi/../../openstack_dashboard/dashboards/project/instances/tables.py", line 386, in single
[Thu Apr 17 13:50:08 2014] [error]     fip = api.network.tenant_floating_ip_allocate(request)
[Thu Apr 17 13:50:08 2014] [error]   File "/usr/share/openstack-dashboard/openstack_dashboard/wsgi/../../openstack_dashboard/api/network.py", line 60, in tenant_floating_ip_allocate
[Thu Apr 17 13:50:08 2014] [error]     return NetworkClient(request).floating_ips.allocate(pool)
[Thu Apr 17 13:50:08 2014] [error]   File "/usr/share/openstack-dashboard/openstack_dashboard/wsgi/../../openstack_dashboard/api/nova.py", line 331, in allocate
[Thu Apr 17 13:50:08 2014] [error]     return FloatingIp(self.client.floating_ips.create(pool=pool))
[Thu Apr 17 13:50:08 2014] [error]   File "/usr/lib/python2.7/dist-packages/novaclient/v1_1/floating_ips.py", line 41, in create
[Thu Apr 17 13:50:08 2014] [error]     return self._create("/os-floating-ips", {'pool': pool}, "floating_ip")
[Thu Apr 17 13:50:08 2014] [error]   File "/usr/lib/python2.7/dist-packages/novaclient/base.py", line 145, in _create
[Thu Apr 17 13:50:08 2014] [error]     _resp, body = self.api.client.post(url, body=body)
[Thu Apr 17 13:50:08 2014] [error]   File "/usr/lib/python2.7/dist-packages/novaclient/client.py", line 232, in post
[Thu Apr 17 13:50:08 2014] [error]     return self._cs_request(url, 'POST', **kwargs)
[Thu Apr 17 13:50:08 2014] [error]   File "/usr/lib/python2.7/dist-packages/novaclient/client.py", line 213, in _cs_request
[Thu Apr 17 13:50:08 2014] [error]     **kwargs)
[Thu Apr 17 13:50:08 2014] [error]   File "/usr/lib/python2.7/dist-packages/novaclient/client.py", line 195, in _time_request
[Thu Apr 17 13:50:08 2014] [error]     resp, body = self.request(url, method, **kwargs)
[Thu Apr 17 13:50:08 2014] [error]   File "/usr/lib/python2.7/dist-packages/novaclient/client.py", line 189, in request
[Thu Apr 17 13:50:08 2014] [error]     raise exceptions.from_response(resp, body, url, method)
[Thu Apr 17 13:50:08 2014] [error] NotFound: No more floating ips available. (HTTP 404) (Request-ID: req-2eb0fb08-57bd-4b99-a947-df802e5372d4)
[Thu Apr 17 14:00:16 2014] [error] Scheduled termination of Instance: "dfire_test3"
[Thu Apr 17 14:00:22 2014] [error] Scheduled termination of Instance: "dfire_test4"
[Thu Apr 17 14:00:32 2014] [error] Not Found: No more floating ips available. (HTTP 404) (Request-ID: req-050bcbae-73f4-4aa0-b695-392858ed8d3d)
[Thu Apr 17 14:00:32 2014] [error] Traceback (most recent call last):
[Thu Apr 17 14:00:32 2014] [error]   File "/usr/share/openstack-dashboard/openstack_dashboard/wsgi/../../openstack_dashboard/dashboards/project/instances/tables.py", line 386, in single
[Thu Apr 17 14:00:32 2014] [error]     fip = api.network.tenant_floating_ip_allocate(request)
[Thu Apr 17 14:00:32 2014] [error]   File "/usr/share/openstack-dashboard/openstack_dashboard/wsgi/../../openstack_dashboard/api/network.py", line 60, in tenant_floating_ip_allocate
[Thu Apr 17 14:00:32 2014] [error]     return NetworkClient(request).floating_ips.allocate(pool)
[Thu Apr 17 14:00:32 2014] [error]   File "/usr/share/openstack-dashboard/openstack_dashboard/wsgi/../../openstack_dashboard/api/nova.py", line 331, in allocate
[Thu Apr 17 14:00:32 2014] [error]     return FloatingIp(self.client.floating_ips.create(pool=pool))
[Thu Apr 17 14:00:32 2014] [error]   File "/usr/lib/python2.7/dist-packages/novaclient/v1_1/floating_ips.py", line 41, in create
[Thu Apr 17 14:00:32 2014] [error]     return self._create("/os-floating-ips", {'pool': pool}, "floating_ip")
[Thu Apr 17 14:00:32 2014] [error]   File "/usr/lib/python2.7/dist-packages/novaclient/base.py", line 145, in _create
[Thu Apr 17 14:00:32 2014] [error]     _resp, body = self.api.client.post(url, body=body)
[Thu Apr 17 14:00:32 2014] [error]   File "/usr/lib/python2.7/dist-packages/novaclient/client.py", line 232, in post
[Thu Apr 17 14:00:32 2014] [error]     return self._cs_request(url, 'POST', **kwargs)
[Thu Apr 17 14:00:32 2014] [error]   File "/usr/lib/python2.7/dist-packages/novaclient/client.py", line 213, in _cs_request
[Thu Apr 17 14:00:32 2014] [error]     **kwargs)
[Thu Apr 17 14:00:32 2014] [error]   File "/usr/lib/python2.7/dist-packages/novaclient/client.py", line 195, in _time_request
[Thu Apr 17 14:00:32 2014] [error]     resp, body = self.request(url, method, **kwargs)
[Thu Apr 17 14:00:32 2014] [error]   File "/usr/lib/python2.7/dist-packages/novaclient/client.py", line 189, in request
[Thu Apr 17 14:00:32 2014] [error]     raise exceptions.from_response(resp, body, url, method)
[Thu Apr 17 14:00:32 2014] [error] NotFound: No more floating ips available. (HTTP 404) (Request-ID: req-050bcbae-73f4-4aa0-b695-392858ed8d3d)
[Thu Apr 17 14:00:47 2014] [error] Shut Off Instance: "dfire_test2"
[Thu Apr 17 14:01:59 2014] [error] Not Found: No more floating ips available. (HTTP 404) (Request-ID: req-3e3bd1bf-4319-4a23-89d3-f01c69158a7a)
[Thu Apr 17 14:01:59 2014] [error] Traceback (most recent call last):
[Thu Apr 17 14:01:59 2014] [error]   File "/usr/share/openstack-dashboard/openstack_dashboard/wsgi/../../openstack_dashboard/dashboards/project/instances/tables.py", line 386, in single
[Thu Apr 17 14:01:59 2014] [error]     fip = api.network.tenant_floating_ip_allocate(request)
[Thu Apr 17 14:01:59 2014] [error]   File "/usr/share/openstack-dashboard/openstack_dashboard/wsgi/../../openstack_dashboard/api/network.py", line 60, in tenant_floating_ip_allocate
[Thu Apr 17 14:01:59 2014] [error]     return NetworkClient(request).floating_ips.allocate(pool)
[Thu Apr 17 14:01:59 2014] [error]   File "/usr/share/openstack-dashboard/openstack_dashboard/wsgi/../../openstack_dashboard/api/nova.py", line 331, in allocate
[Thu Apr 17 14:01:59 2014] [error]     return FloatingIp(self.client.floating_ips.create(pool=pool))
[Thu Apr 17 14:01:59 2014] [error]   File "/usr/lib/python2.7/dist-packages/novaclient/v1_1/floating_ips.py", line 41, in create
[Thu Apr 17 14:01:59 2014] [error]     return self._create("/os-floating-ips", {'pool': pool}, "floating_ip")
[Thu Apr 17 14:01:59 2014] [error]   File "/usr/lib/python2.7/dist-packages/novaclient/base.py", line 145, in _create
[Thu Apr 17 14:01:59 2014] [error]     _resp, body = self.api.client.post(url, body=body)
[Thu Apr 17 14:01:59 2014] [error]   File "/usr/lib/python2.7/dist-packages/novaclient/client.py", line 232, in post
[Thu Apr 17 14:01:59 2014] [error]     return self._cs_request(url, 'POST', **kwargs)
[Thu Apr 17 14:01:59 2014] [error]   File "/usr/lib/python2.7/dist-packages/novaclient/client.py", line 213, in _cs_request
[Thu Apr 17 14:01:59 2014] [error]     **kwargs)
[Thu Apr 17 14:01:59 2014] [error]   File "/usr/lib/python2.7/dist-packages/novaclient/client.py", line 195, in _time_request
[Thu Apr 17 14:01:59 2014] [error]     resp, body = self.request(url, method, **kwargs)
[Thu Apr 17 14:01:59 2014] [error]   File "/usr/lib/python2.7/dist-packages/novaclient/client.py", line 189, in request
[Thu Apr 17 14:01:59 2014] [error]     raise exceptions.from_response(resp, body, url, method)
[Thu Apr 17 14:01:59 2014] [error] NotFound: No more floating ips available. (HTTP 404) (Request-ID: req-3e3bd1bf-4319-4a23-89d3-f01c69158a7a)
[Thu Apr 17 14:02:00 2014] [error] [client 137.43.154.74] File does not exist: /var/www/auth, referer: http://137.43.154.99/horizon/auth/login/
[Thu Apr 17 14:02:09 2014] [error] Not Found: No more floating ips available. (HTTP 404) (Request-ID: req-5c3a3f9c-f58a-41e9-810c-9763e7dd1118)
[Thu Apr 17 14:02:09 2014] [error] Traceback (most recent call last):
[Thu Apr 17 14:02:09 2014] [error]   File "/usr/share/openstack-dashboard/openstack_dashboard/wsgi/../../openstack_dashboard/dashboards/project/instances/tables.py", line 386, in single
[Thu Apr 17 14:02:09 2014] [error]     fip = api.network.tenant_floating_ip_allocate(request)
[Thu Apr 17 14:02:09 2014] [error]   File "/usr/share/openstack-dashboard/openstack_dashboard/wsgi/../../openstack_dashboard/api/network.py", line 60, in tenant_floating_ip_allocate
[Thu Apr 17 14:02:09 2014] [error]     return NetworkClient(request).floating_ips.allocate(pool)
[Thu Apr 17 14:02:09 2014] [error]   File "/usr/share/openstack-dashboard/openstack_dashboard/wsgi/../../openstack_dashboard/api/nova.py", line 331, in allocate
[Thu Apr 17 14:02:09 2014] [error]     return FloatingIp(self.client.floating_ips.create(pool=pool))
[Thu Apr 17 14:02:09 2014] [error]   File "/usr/lib/python2.7/dist-packages/novaclient/v1_1/floating_ips.py", line 41, in create
[Thu Apr 17 14:02:09 2014] [error]     return self._create("/os-floating-ips", {'pool': pool}, "floating_ip")
[Thu Apr 17 14:02:09 2014] [error]   File "/usr/lib/python2.7/dist-packages/novaclient/base.py", line 145, in _create
[Thu Apr 17 14:02:09 2014] [error]     _resp, body = self.api.client.post(url, body=body)
[Thu Apr 17 14:02:09 2014] [error]   File "/usr/lib/python2.7/dist-packages/novaclient/client.py", line 232, in post
[Thu Apr 17 14:02:09 2014] [error]     return self._cs_request(url, 'POST', **kwargs)
[Thu Apr 17 14:02:09 2014] [error]   File "/usr/lib/python2.7/dist-packages/novaclient/client.py", line 213, in _cs_request
[Thu Apr 17 14:02:09 2014] [error]     **kwargs)
[Thu Apr 17 14:02:09 2014] [error]   File "/usr/lib/python2.7/dist-packages/novaclient/client.py", line 195, in _time_request
[Thu Apr 17 14:02:09 2014] [error]     resp, body = self.request(url, method, **kwargs)
[Thu Apr 17 14:02:09 2014] [error]   File "/usr/lib/python2.7/dist-packages/novaclient/client.py", line 189, in request
[Thu Apr 17 14:02:09 2014] [error]     raise exceptions.from_response(resp, body, url, method)
[Thu Apr 17 14:02:09 2014] [error] NotFound: No more floating ips available. (HTTP 404) (Request-ID: req-5c3a3f9c-f58a-41e9-810c-9763e7dd1118)
[Thu Apr 17 14:02:12 2014] [error] Started Instance: "dfire_test2"
[Thu Apr 17 14:02:21 2014] [error] Not Found: No more floating ips available. (HTTP 404) (Request-ID: req-efa82361-744f-4776-8842-49328481e8d4)
[Thu Apr 17 14:02:21 2014] [error] Traceback (most recent call last):
[Thu Apr 17 14:02:21 2014] [error]   File "/usr/share/openstack-dashboard/openstack_dashboard/wsgi/../../openstack_dashboard/dashboards/project/instances/tables.py", line 386, in single
[Thu Apr 17 14:02:21 2014] [error]     fip = api.network.tenant_floating_ip_allocate(request)
[Thu Apr 17 14:02:21 2014] [error]   File "/usr/share/openstack-dashboard/openstack_dashboard/wsgi/../../openstack_dashboard/api/network.py", line 60, in tenant_floating_ip_allocate
[Thu Apr 17 14:02:21 2014] [error]     return NetworkClient(request).floating_ips.allocate(pool)
[Thu Apr 17 14:02:21 2014] [error]   File "/usr/share/openstack-dashboard/openstack_dashboard/wsgi/../../openstack_dashboard/api/nova.py", line 331, in allocate
[Thu Apr 17 14:02:21 2014] [error]     return FloatingIp(self.client.floating_ips.create(pool=pool))
[Thu Apr 17 14:02:21 2014] [error]   File "/usr/lib/python2.7/dist-packages/novaclient/v1_1/floating_ips.py", line 41, in create
[Thu Apr 17 14:02:21 2014] [error]     return self._create("/os-floating-ips", {'pool': pool}, "floating_ip")
[Thu Apr 17 14:02:21 2014] [error]   File "/usr/lib/python2.7/dist-packages/novaclient/base.py", line 145, in _create
[Thu Apr 17 14:02:21 2014] [error]     _resp, body = self.api.client.post(url, body=body)
[Thu Apr 17 14:02:21 2014] [error]   File "/usr/lib/python2.7/dist-packages/novaclient/client.py", line 232, in post
[Thu Apr 17 14:02:21 2014] [error]     return self._cs_request(url, 'POST', **kwargs)
[Thu Apr 17 14:02:21 2014] [error]   File "/usr/lib/python2.7/dist-packages/novaclient/client.py", line 213, in _cs_request
[Thu Apr 17 14:02:21 2014] [error]     **kwargs)
[Thu Apr 17 14:02:21 2014] [error]   File "/usr/lib/python2.7/dist-packages/novaclient/client.py", line 195, in _time_request
[Thu Apr 17 14:02:21 2014] [error]     resp, body = self.request(url, method, **kwargs)
[Thu Apr 17 14:02:21 2014] [error]   File "/usr/lib/python2.7/dist-packages/novaclient/client.py", line 189, in request
[Thu Apr 17 14:02:21 2014] [error]     raise exceptions.from_response(resp, body, url, method)
[Thu Apr 17 14:02:21 2014] [error] NotFound: No more floating ips available. (HTTP 404) (Request-ID: req-efa82361-744f-4776-8842-49328481e8d4)
[Thu Apr 17 14:15:45 2014] [notice] caught SIGTERM, shutting down
[Thu Apr 17 14:16:50 2014] [warn] mod_wsgi: Compiled for Python/2.7.2+.
[Thu Apr 17 14:16:50 2014] [warn] mod_wsgi: Runtime using Python/2.7.3.
[Thu Apr 17 14:16:50 2014] [notice] Apache/2.2.22 (Ubuntu) mod_wsgi/3.3 Python/2.7.3 configured -- resuming normal operations
[Thu Apr 17 14:19:49 2014] [error] Not Found: No more floating ips available. (HTTP 404) (Request-ID: req-4449f40f-1904-42d8-a423-025ac6ef3cd9)
[Thu Apr 17 14:19:49 2014] [error] Traceback (most recent call last):
[Thu Apr 17 14:19:49 2014] [error]   File "/usr/share/openstack-dashboard/openstack_dashboard/wsgi/../../openstack_dashboard/dashboards/project/instances/tables.py", line 386, in single
[Thu Apr 17 14:19:49 2014] [error]     fip = api.network.tenant_floating_ip_allocate(request)
[Thu Apr 17 14:19:49 2014] [error]   File "/usr/share/openstack-dashboard/openstack_dashboard/wsgi/../../openstack_dashboard/api/network.py", line 60, in tenant_floating_ip_allocate
[Thu Apr 17 14:19:49 2014] [error]     return NetworkClient(request).floating_ips.allocate(pool)
[Thu Apr 17 14:19:49 2014] [error]   File "/usr/share/openstack-dashboard/openstack_dashboard/wsgi/../../openstack_dashboard/api/nova.py", line 331, in allocate
[Thu Apr 17 14:19:49 2014] [error]     return FloatingIp(self.client.floating_ips.create(pool=pool))
[Thu Apr 17 14:19:49 2014] [error]   File "/usr/lib/python2.7/dist-packages/novaclient/v1_1/floating_ips.py", line 41, in create
[Thu Apr 17 14:19:49 2014] [error]     return self._create("/os-floating-ips", {'pool': pool}, "floating_ip")
[Thu Apr 17 14:19:49 2014] [error]   File "/usr/lib/python2.7/dist-packages/novaclient/base.py", line 145, in _create
[Thu Apr 17 14:19:49 2014] [error]     _resp, body = self.api.client.post(url, body=body)
[Thu Apr 17 14:19:49 2014] [error]   File "/usr/lib/python2.7/dist-packages/novaclient/client.py", line 232, in post
[Thu Apr 17 14:19:49 2014] [error]     return self._cs_request(url, 'POST', **kwargs)
[Thu Apr 17 14:19:49 2014] [error]   File "/usr/lib/python2.7/dist-packages/novaclient/client.py", line 213, in _cs_request
[Thu Apr 17 14:19:49 2014] [error]     **kwargs)
[Thu Apr 17 14:19:49 2014] [error]   File "/usr/lib/python2.7/dist-packages/novaclient/client.py", line 195, in _time_request
[Thu Apr 17 14:19:49 2014] [error]     resp, body = self.request(url, method, **kwargs)
[Thu Apr 17 14:19:49 2014] [error]   File "/usr/lib/python2.7/dist-packages/novaclient/client.py", line 189, in request
[Thu Apr 17 14:19:49 2014] [error]     raise exceptions.from_response(resp, body, url, method)
[Thu Apr 17 14:19:49 2014] [error] NotFound: No more floating ips available. (HTTP 404) (Request-ID: req-4449f40f-1904-42d8-a423-025ac6ef3cd9)
[Thu Apr 17 14:37:25 2014] [notice] caught SIGTERM, shutting down
[Thu Apr 17 14:38:30 2014] [warn] mod_wsgi: Compiled for Python/2.7.2+.
[Thu Apr 17 14:38:30 2014] [warn] mod_wsgi: Runtime using Python/2.7.3.
[Thu Apr 17 14:38:30 2014] [notice] Apache/2.2.22 (Ubuntu) mod_wsgi/3.3 Python/2.7.3 configured -- resuming normal operations
[Thu Apr 17 16:02:51 2014] [error] Problem instantiating action class.
[Thu Apr 17 16:02:51 2014] [error] Traceback (most recent call last):
[Thu Apr 17 16:02:51 2014] [error]   File "/usr/lib/python2.7/dist-packages/horizon/workflows/base.py", line 376, in action
[Thu Apr 17 16:02:51 2014] [error]     context)
[Thu Apr 17 16:02:51 2014] [error]   File "/usr/share/openstack-dashboard/openstack_dashboard/wsgi/../../openstack_dashboard/dashboards/admin/projects/workflows.py", line 167, in __init__
[Thu Apr 17 16:02:51 2014] [error]     redirect=reverse(INDEX_URL))
[Thu Apr 17 16:02:51 2014] [error]   File "/usr/share/openstack-dashboard/openstack_dashboard/wsgi/../../openstack_dashboard/dashboards/admin/projects/workflows.py", line 163, in __init__
[Thu Apr 17 16:02:51 2014] [error]     raise exceptions.NotFound(msg)
[Thu Apr 17 16:02:51 2014] [error] NotFound: Could not find default role "Member" in Keystone
[Thu Apr 17 16:02:51 2014] [error] Internal Server Error: /horizon/admin/projects/create
[Thu Apr 17 16:02:51 2014] [error] Traceback (most recent call last):
[Thu Apr 17 16:02:51 2014] [error]   File "/usr/lib/python2.7/dist-packages/django/core/handlers/base.py", line 140, in get_response
[Thu Apr 17 16:02:51 2014] [error]     response = response.render()
[Thu Apr 17 16:02:51 2014] [error]   File "/usr/lib/python2.7/dist-packages/django/template/response.py", line 105, in render
[Thu Apr 17 16:02:51 2014] [error]     self.content = self.rendered_content
[Thu Apr 17 16:02:51 2014] [error]   File "/usr/lib/python2.7/dist-packages/django/template/response.py", line 82, in rendered_content
[Thu Apr 17 16:02:51 2014] [error]     content = template.render(context)
[Thu Apr 17 16:02:51 2014] [error]   File "/usr/lib/python2.7/dist-packages/django/template/base.py", line 140, in render
[Thu Apr 17 16:02:51 2014] [error]     return self._render(context)
[Thu Apr 17 16:02:51 2014] [error]   File "/usr/lib/python2.7/dist-packages/django/template/base.py", line 134, in _render
[Thu Apr 17 16:02:51 2014] [error]     return self.nodelist.render(context)
[Thu Apr 17 16:02:51 2014] [error]   File "/usr/lib/python2.7/dist-packages/django/template/base.py", line 830, in render
[Thu Apr 17 16:02:51 2014] [error]     bit = self.render_node(node, context)
[Thu Apr 17 16:02:51 2014] [error]   File "/usr/lib/python2.7/dist-packages/django/template/base.py", line 844, in render_node
[Thu Apr 17 16:02:51 2014] [error]     return node.render(context)
[Thu Apr 17 16:02:51 2014] [error]   File "/usr/lib/python2.7/dist-packages/django/template/defaulttags.py", line 485, in render
[Thu Apr 17 16:02:51 2014] [error]     output = self.nodelist.render(context)
[Thu Apr 17 16:02:51 2014] [error]   File "/usr/lib/python2.7/dist-packages/django/template/base.py", line 830, in render
[Thu Apr 17 16:02:51 2014] [error]     bit = self.render_node(node, context)
[Thu Apr 17 16:02:51 2014] [error]   File "/usr/lib/python2.7/dist-packages/django/template/base.py", line 844, in render_node
[Thu Apr 17 16:02:51 2014] [error]     return node.render(context)
[Thu Apr 17 16:02:51 2014] [error]   File "/usr/lib/python2.7/dist-packages/django/template/loader_tags.py", line 54, in render
[Thu Apr 17 16:02:51 2014] [error]     result = self.nodelist.render(context)
[Thu Apr 17 16:02:51 2014] [error]   File "/usr/lib/python2.7/dist-packages/django/template/base.py", line 830, in render
[Thu Apr 17 16:02:51 2014] [error]     bit = self.render_node(node, context)
[Thu Apr 17 16:02:51 2014] [error]   File "/usr/lib/python2.7/dist-packages/django/template/base.py", line 844, in render_node
[Thu Apr 17 16:02:51 2014] [error]     return node.render(context)
[Thu Apr 17 16:02:51 2014] [error]   File "/usr/lib/python2.7/dist-packages/django/template/defaulttags.py", line 196, in render
[Thu Apr 17 16:02:51 2014] [error]     nodelist.append(node.render(context))
[Thu Apr 17 16:02:51 2014] [error]   File "/usr/lib/python2.7/dist-packages/django/template/defaulttags.py", line 278, in render
[Thu Apr 17 16:02:51 2014] [error]     match = condition.eval(context)
[Thu Apr 17 16:02:51 2014] [error]   File "/usr/lib/python2.7/dist-packages/django/template/defaulttags.py", line 830, in eval
[Thu Apr 17 16:02:51 2014] [error]     return self.value.resolve(context, ignore_failures=True)
[Thu Apr 17 16:02:51 2014] [error]   File "/usr/lib/python2.7/dist-packages/django/template/base.py", line 578, in resolve
[Thu Apr 17 16:02:51 2014] [error]     obj = self.var.resolve(context)
[Thu Apr 17 16:02:51 2014] [error]   File "/usr/lib/python2.7/dist-packages/django/template/base.py", line 728, in resolve
[Thu Apr 17 16:02:51 2014] [error]     value = self._resolve_lookup(context)
[Thu Apr 17 16:02:51 2014] [error]   File "/usr/lib/python2.7/dist-packages/django/template/base.py", line 779, in _resolve_lookup
[Thu Apr 17 16:02:51 2014] [error]     current = current()
[Thu Apr 17 16:02:51 2014] [error]   File "/usr/lib/python2.7/dist-packages/horizon/workflows/base.py", line 451, in has_required_fields
[Thu Apr 17 16:02:51 2014] [error]     return any(field.required for field in self.action.fields.values())
[Thu Apr 17 16:02:51 2014] [error]   File "/usr/lib/python2.7/dist-packages/horizon/workflows/base.py", line 376, in action
[Thu Apr 17 16:02:51 2014] [error]     context)
[Thu Apr 17 16:02:51 2014] [error]   File "/usr/share/openstack-dashboard/openstack_dashboard/wsgi/../../openstack_dashboard/dashboards/admin/projects/workflows.py", line 167, in __init__
[Thu Apr 17 16:02:51 2014] [error]     redirect=reverse(INDEX_URL))
[Thu Apr 17 16:02:51 2014] [error]   File "/usr/share/openstack-dashboard/openstack_dashboard/wsgi/../../openstack_dashboard/dashboards/admin/projects/workflows.py", line 163, in __init__
[Thu Apr 17 16:02:51 2014] [error]     raise exceptions.NotFound(msg)
[Thu Apr 17 16:02:51 2014] [error] NotFound: Could not find default role "Member" in Keystone
[Thu Apr 17 16:03:01 2014] [error] Problem instantiating action class.
[Thu Apr 17 16:03:01 2014] [error] Traceback (most recent call last):
[Thu Apr 17 16:03:01 2014] [error]   File "/usr/lib/python2.7/dist-packages/horizon/workflows/base.py", line 376, in action
[Thu Apr 17 16:03:01 2014] [error]     context)
[Thu Apr 17 16:03:01 2014] [error]   File "/usr/share/openstack-dashboard/openstack_dashboard/wsgi/../../openstack_dashboard/dashboards/admin/projects/workflows.py", line 167, in __init__
[Thu Apr 17 16:03:01 2014] [error]     redirect=reverse(INDEX_URL))
[Thu Apr 17 16:03:01 2014] [error]   File "/usr/share/openstack-dashboard/openstack_dashboard/wsgi/../../openstack_dashboard/dashboards/admin/projects/workflows.py", line 163, in __init__
[Thu Apr 17 16:03:01 2014] [error]     raise exceptions.NotFound(msg)
[Thu Apr 17 16:03:01 2014] [error] NotFound: Could not find default role "Member" in Keystone
[Thu Apr 17 16:03:01 2014] [error] Internal Server Error: /horizon/admin/projects/create
[Thu Apr 17 16:03:01 2014] [error] Traceback (most recent call last):
[Thu Apr 17 16:03:01 2014] [error]   File "/usr/lib/python2.7/dist-packages/django/core/handlers/base.py", line 140, in get_response
[Thu Apr 17 16:03:01 2014] [error]     response = response.render()
[Thu Apr 17 16:03:01 2014] [error]   File "/usr/lib/python2.7/dist-packages/django/template/response.py", line 105, in render
[Thu Apr 17 16:03:01 2014] [error]     self.content = self.rendered_content
[Thu Apr 17 16:03:01 2014] [error]   File "/usr/lib/python2.7/dist-packages/django/template/response.py", line 82, in rendered_content
[Thu Apr 17 16:03:01 2014] [error]     content = template.render(context)
[Thu Apr 17 16:03:01 2014] [error]   File "/usr/lib/python2.7/dist-packages/django/template/base.py", line 140, in render
[Thu Apr 17 16:03:01 2014] [error]     return self._render(context)
[Thu Apr 17 16:03:01 2014] [error]   File "/usr/lib/python2.7/dist-packages/django/template/base.py", line 134, in _render
[Thu Apr 17 16:03:01 2014] [error]     return self.nodelist.render(context)
[Thu Apr 17 16:03:01 2014] [error]   File "/usr/lib/python2.7/dist-packages/django/template/base.py", line 830, in render
[Thu Apr 17 16:03:01 2014] [error]     bit = self.render_node(node, context)
[Thu Apr 17 16:03:01 2014] [error]   File "/usr/lib/python2.7/dist-packages/django/template/base.py", line 844, in render_node
[Thu Apr 17 16:03:01 2014] [error]     return node.render(context)
[Thu Apr 17 16:03:01 2014] [error]   File "/usr/lib/python2.7/dist-packages/django/template/defaulttags.py", line 485, in render
[Thu Apr 17 16:03:01 2014] [error]     output = self.nodelist.render(context)
[Thu Apr 17 16:03:01 2014] [error]   File "/usr/lib/python2.7/dist-packages/django/template/base.py", line 830, in render
[Thu Apr 17 16:03:01 2014] [error]     bit = self.render_node(node, context)
[Thu Apr 17 16:03:01 2014] [error]   File "/usr/lib/python2.7/dist-packages/django/template/base.py", line 844, in render_node
[Thu Apr 17 16:03:01 2014] [error]     return node.render(context)
[Thu Apr 17 16:03:01 2014] [error]   File "/usr/lib/python2.7/dist-packages/django/template/loader_tags.py", line 54, in render
[Thu Apr 17 16:03:01 2014] [error]     result = self.nodelist.render(context)
[Thu Apr 17 16:03:01 2014] [error]   File "/usr/lib/python2.7/dist-packages/django/template/base.py", line 830, in render
[Thu Apr 17 16:03:01 2014] [error]     bit = self.render_node(node, context)
[Thu Apr 17 16:03:01 2014] [error]   File "/usr/lib/python2.7/dist-packages/django/template/base.py", line 844, in render_node
[Thu Apr 17 16:03:01 2014] [error]     return node.render(context)
[Thu Apr 17 16:03:01 2014] [error]   File "/usr/lib/python2.7/dist-packages/django/template/defaulttags.py", line 196, in render
[Thu Apr 17 16:03:01 2014] [error]     nodelist.append(node.render(context))
[Thu Apr 17 16:03:01 2014] [error]   File "/usr/lib/python2.7/dist-packages/django/template/defaulttags.py", line 278, in render
[Thu Apr 17 16:03:01 2014] [error]     match = condition.eval(context)
[Thu Apr 17 16:03:01 2014] [error]   File "/usr/lib/python2.7/dist-packages/django/template/defaulttags.py", line 830, in eval
[Thu Apr 17 16:03:01 2014] [error]     return self.value.resolve(context, ignore_failures=True)
[Thu Apr 17 16:03:01 2014] [error]   File "/usr/lib/python2.7/dist-packages/django/template/base.py", line 578, in resolve
[Thu Apr 17 16:03:01 2014] [error]     obj = self.var.resolve(context)
[Thu Apr 17 16:03:01 2014] [error]   File "/usr/lib/python2.7/dist-packages/django/template/base.py", line 728, in resolve
[Thu Apr 17 16:03:01 2014] [error]     value = self._resolve_lookup(context)
[Thu Apr 17 16:03:01 2014] [error]   File "/usr/lib/python2.7/dist-packages/django/template/base.py", line 779, in _resolve_lookup
[Thu Apr 17 16:03:01 2014] [error]     current = current()
[Thu Apr 17 16:03:01 2014] [error]   File "/usr/lib/python2.7/dist-packages/horizon/workflows/base.py", line 451, in has_required_fields
[Thu Apr 17 16:03:01 2014] [error]     return any(field.required for field in self.action.fields.values())
[Thu Apr 17 16:03:01 2014] [error]   File "/usr/lib/python2.7/dist-packages/horizon/workflows/base.py", line 376, in action
[Thu Apr 17 16:03:01 2014] [error]     context)
[Thu Apr 17 16:03:01 2014] [error]   File "/usr/share/openstack-dashboard/openstack_dashboard/wsgi/../../openstack_dashboard/dashboards/admin/projects/workflows.py", line 167, in __init__
[Thu Apr 17 16:03:01 2014] [error]     redirect=reverse(INDEX_URL))
[Thu Apr 17 16:03:01 2014] [error]   File "/usr/share/openstack-dashboard/openstack_dashboard/wsgi/../../openstack_dashboard/dashboards/admin/projects/workflows.py", line 163, in __init__
[Thu Apr 17 16:03:01 2014] [error]     raise exceptions.NotFound(msg)
[Thu Apr 17 16:03:01 2014] [error] NotFound: Could not find default role "Member" in Keystone
[Thu Apr 17 16:06:10 2014] [error] Problem instantiating action class.
[Thu Apr 17 16:06:10 2014] [error] Traceback (most recent call last):
[Thu Apr 17 16:06:10 2014] [error]   File "/usr/lib/python2.7/dist-packages/horizon/workflows/base.py", line 376, in action
[Thu Apr 17 16:06:10 2014] [error]     context)
[Thu Apr 17 16:06:10 2014] [error]   File "/usr/share/openstack-dashboard/openstack_dashboard/wsgi/../../openstack_dashboard/dashboards/admin/projects/workflows.py", line 167, in __init__
[Thu Apr 17 16:06:10 2014] [error]     redirect=reverse(INDEX_URL))
[Thu Apr 17 16:06:10 2014] [error]   File "/usr/share/openstack-dashboard/openstack_dashboard/wsgi/../../openstack_dashboard/dashboards/admin/projects/workflows.py", line 163, in __init__
[Thu Apr 17 16:06:10 2014] [error]     raise exceptions.NotFound(msg)
[Thu Apr 17 16:06:10 2014] [error] NotFound: Could not find default role "Member" in Keystone
[Thu Apr 17 16:06:10 2014] [error] Internal Server Error: /horizon/admin/projects/create
[Thu Apr 17 16:06:10 2014] [error] Traceback (most recent call last):
[Thu Apr 17 16:06:10 2014] [error]   File "/usr/lib/python2.7/dist-packages/django/core/handlers/base.py", line 140, in get_response
[Thu Apr 17 16:06:10 2014] [error]     response = response.render()
[Thu Apr 17 16:06:10 2014] [error]   File "/usr/lib/python2.7/dist-packages/django/template/response.py", line 105, in render
[Thu Apr 17 16:06:10 2014] [error]     self.content = self.rendered_content
[Thu Apr 17 16:06:10 2014] [error]   File "/usr/lib/python2.7/dist-packages/django/template/response.py", line 82, in rendered_content
[Thu Apr 17 16:06:10 2014] [error]     content = template.render(context)
[Thu Apr 17 16:06:10 2014] [error]   File "/usr/lib/python2.7/dist-packages/django/template/base.py", line 140, in render
[Thu Apr 17 16:06:10 2014] [error]     return self._render(context)
[Thu Apr 17 16:06:10 2014] [error]   File "/usr/lib/python2.7/dist-packages/django/template/base.py", line 134, in _render
[Thu Apr 17 16:06:10 2014] [error]     return self.nodelist.render(context)
[Thu Apr 17 16:06:10 2014] [error]   File "/usr/lib/python2.7/dist-packages/django/template/base.py", line 830, in render
[Thu Apr 17 16:06:10 2014] [error]     bit = self.render_node(node, context)
[Thu Apr 17 16:06:10 2014] [error]   File "/usr/lib/python2.7/dist-packages/django/template/base.py", line 844, in render_node
[Thu Apr 17 16:06:10 2014] [error]     return node.render(context)
[Thu Apr 17 16:06:10 2014] [error]   File "/usr/lib/python2.7/dist-packages/django/template/defaulttags.py", line 485, in render
[Thu Apr 17 16:06:10 2014] [error]     output = self.nodelist.render(context)
[Thu Apr 17 16:06:10 2014] [error]   File "/usr/lib/python2.7/dist-packages/django/template/base.py", line 830, in render
[Thu Apr 17 16:06:10 2014] [error]     bit = self.render_node(node, context)
[Thu Apr 17 16:06:10 2014] [error]   File "/usr/lib/python2.7/dist-packages/django/template/base.py", line 844, in render_node
[Thu Apr 17 16:06:10 2014] [error]     return node.render(context)
[Thu Apr 17 16:06:10 2014] [error]   File "/usr/lib/python2.7/dist-packages/django/template/loader_tags.py", line 54, in render
[Thu Apr 17 16:06:10 2014] [error]     result = self.nodelist.render(context)
[Thu Apr 17 16:06:10 2014] [error]   File "/usr/lib/python2.7/dist-packages/django/template/base.py", line 830, in render
[Thu Apr 17 16:06:10 2014] [error]     bit = self.render_node(node, context)
[Thu Apr 17 16:06:10 2014] [error]   File "/usr/lib/python2.7/dist-packages/django/template/base.py", line 844, in render_node
[Thu Apr 17 16:06:10 2014] [error]     return node.render(context)
[Thu Apr 17 16:06:10 2014] [error]   File "/usr/lib/python2.7/dist-packages/django/template/defaulttags.py", line 196, in render
[Thu Apr 17 16:06:10 2014] [error]     nodelist.append(node.render(context))
[Thu Apr 17 16:06:10 2014] [error]   File "/usr/lib/python2.7/dist-packages/django/template/defaulttags.py", line 278, in render
[Thu Apr 17 16:06:10 2014] [error]     match = condition.eval(context)
[Thu Apr 17 16:06:10 2014] [error]   File "/usr/lib/python2.7/dist-packages/django/template/defaulttags.py", line 830, in eval
[Thu Apr 17 16:06:10 2014] [error]     return self.value.resolve(context, ignore_failures=True)
[Thu Apr 17 16:06:10 2014] [error]   File "/usr/lib/python2.7/dist-packages/django/template/base.py", line 578, in resolve
[Thu Apr 17 16:06:10 2014] [error]     obj = self.var.resolve(context)
[Thu Apr 17 16:06:10 2014] [error]   File "/usr/lib/python2.7/dist-packages/django/template/base.py", line 728, in resolve
[Thu Apr 17 16:06:10 2014] [error]     value = self._resolve_lookup(context)
[Thu Apr 17 16:06:10 2014] [error]   File "/usr/lib/python2.7/dist-packages/django/template/base.py", line 779, in _resolve_lookup
[Thu Apr 17 16:06:10 2014] [error]     current = current()
[Thu Apr 17 16:06:10 2014] [error]   File "/usr/lib/python2.7/dist-packages/horizon/workflows/base.py", line 451, in has_required_fields
[Thu Apr 17 16:06:10 2014] [error]     return any(field.required for field in self.action.fields.values())
[Thu Apr 17 16:06:10 2014] [error]   File "/usr/lib/python2.7/dist-packages/horizon/workflows/base.py", line 376, in action
[Thu Apr 17 16:06:10 2014] [error]     context)
[Thu Apr 17 16:06:10 2014] [error]   File "/usr/share/openstack-dashboard/openstack_dashboard/wsgi/../../openstack_dashboard/dashboards/admin/projects/workflows.py", line 167, in __init__
[Thu Apr 17 16:06:10 2014] [error]     redirect=reverse(INDEX_URL))
[Thu Apr 17 16:06:10 2014] [error]   File "/usr/share/openstack-dashboard/openstack_dashboard/wsgi/../../openstack_dashboard/dashboards/admin/projects/workflows.py", line 163, in __init__
[Thu Apr 17 16:06:10 2014] [error]     raise exceptions.NotFound(msg)
[Thu Apr 17 16:06:10 2014] [error] NotFound: Could not find default role "Member" in Keystone
[Thu Apr 17 16:14:50 2014] [error] Problem instantiating action class.
[Thu Apr 17 16:14:50 2014] [error] Traceback (most recent call last):
[Thu Apr 17 16:14:50 2014] [error]   File "/usr/lib/python2.7/dist-packages/horizon/workflows/base.py", line 376, in action
[Thu Apr 17 16:14:50 2014] [error]     context)
[Thu Apr 17 16:14:50 2014] [error]   File "/usr/share/openstack-dashboard/openstack_dashboard/wsgi/../../openstack_dashboard/dashboards/admin/projects/workflows.py", line 167, in __init__
[Thu Apr 17 16:14:50 2014] [error]     redirect=reverse(INDEX_URL))
[Thu Apr 17 16:14:50 2014] [error]   File "/usr/share/openstack-dashboard/openstack_dashboard/wsgi/../../openstack_dashboard/dashboards/admin/projects/workflows.py", line 163, in __init__
[Thu Apr 17 16:14:50 2014] [error]     raise exceptions.NotFound(msg)
[Thu Apr 17 16:14:50 2014] [error] NotFound: Could not find default role "Member" in Keystone
[Thu Apr 17 16:14:50 2014] [error] Internal Server Error: /horizon/admin/projects/create
[Thu Apr 17 16:14:50 2014] [error] Traceback (most recent call last):
[Thu Apr 17 16:14:50 2014] [error]   File "/usr/lib/python2.7/dist-packages/django/core/handlers/base.py", line 140, in get_response
[Thu Apr 17 16:14:50 2014] [error]     response = response.render()
[Thu Apr 17 16:14:50 2014] [error]   File "/usr/lib/python2.7/dist-packages/django/template/response.py", line 105, in render
[Thu Apr 17 16:14:50 2014] [error]     self.content = self.rendered_content
[Thu Apr 17 16:14:50 2014] [error]   File "/usr/lib/python2.7/dist-packages/django/template/response.py", line 82, in rendered_content
[Thu Apr 17 16:14:50 2014] [error]     content = template.render(context)
[Thu Apr 17 16:14:50 2014] [error]   File "/usr/lib/python2.7/dist-packages/django/template/base.py", line 140, in render
[Thu Apr 17 16:14:50 2014] [error]     return self._render(context)
[Thu Apr 17 16:14:50 2014] [error]   File "/usr/lib/python2.7/dist-packages/django/template/base.py", line 134, in _render
[Thu Apr 17 16:14:50 2014] [error]     return self.nodelist.render(context)
[Thu Apr 17 16:14:50 2014] [error]   File "/usr/lib/python2.7/dist-packages/django/template/base.py", line 830, in render
[Thu Apr 17 16:14:50 2014] [error]     bit = self.render_node(node, context)
[Thu Apr 17 16:14:50 2014] [error]   File "/usr/lib/python2.7/dist-packages/django/template/base.py", line 844, in render_node
[Thu Apr 17 16:14:50 2014] [error]     return node.render(context)
[Thu Apr 17 16:14:50 2014] [error]   File "/usr/lib/python2.7/dist-packages/django/template/defaulttags.py", line 485, in render
[Thu Apr 17 16:14:50 2014] [error]     output = self.nodelist.render(context)
[Thu Apr 17 16:14:50 2014] [error]   File "/usr/lib/python2.7/dist-packages/django/template/base.py", line 830, in render
[Thu Apr 17 16:14:50 2014] [error]     bit = self.render_node(node, context)
[Thu Apr 17 16:14:50 2014] [error]   File "/usr/lib/python2.7/dist-packages/django/template/base.py", line 844, in render_node
[Thu Apr 17 16:14:50 2014] [error]     return node.render(context)
[Thu Apr 17 16:14:50 2014] [error]   File "/usr/lib/python2.7/dist-packages/django/template/loader_tags.py", line 54, in render
[Thu Apr 17 16:14:50 2014] [error]     result = self.nodelist.render(context)
[Thu Apr 17 16:14:50 2014] [error]   File "/usr/lib/python2.7/dist-packages/django/template/base.py", line 830, in render
[Thu Apr 17 16:14:50 2014] [error]     bit = self.render_node(node, context)
[Thu Apr 17 16:14:50 2014] [error]   File "/usr/lib/python2.7/dist-packages/django/template/base.py", line 844, in render_node
[Thu Apr 17 16:14:50 2014] [error]     return node.render(context)
[Thu Apr 17 16:14:50 2014] [error]   File "/usr/lib/python2.7/dist-packages/django/template/defaulttags.py", line 196, in render
[Thu Apr 17 16:14:50 2014] [error]     nodelist.append(node.render(context))
[Thu Apr 17 16:14:50 2014] [error]   File "/usr/lib/python2.7/dist-packages/django/template/defaulttags.py", line 278, in render
[Thu Apr 17 16:14:50 2014] [error]     match = condition.eval(context)
[Thu Apr 17 16:14:50 2014] [error]   File "/usr/lib/python2.7/dist-packages/django/template/defaulttags.py", line 830, in eval
[Thu Apr 17 16:14:50 2014] [error]     return self.value.resolve(context, ignore_failures=True)
[Thu Apr 17 16:14:50 2014] [error]   File "/usr/lib/python2.7/dist-packages/django/template/base.py", line 578, in resolve
[Thu Apr 17 16:14:50 2014] [error]     obj = self.var.resolve(context)
[Thu Apr 17 16:14:50 2014] [error]   File "/usr/lib/python2.7/dist-packages/django/template/base.py", line 728, in resolve
[Thu Apr 17 16:14:50 2014] [error]     value = self._resolve_lookup(context)
[Thu Apr 17 16:14:50 2014] [error]   File "/usr/lib/python2.7/dist-packages/django/template/base.py", line 779, in _resolve_lookup
[Thu Apr 17 16:14:50 2014] [error]     current = current()
[Thu Apr 17 16:14:50 2014] [error]   File "/usr/lib/python2.7/dist-packages/horizon/workflows/base.py", line 451, in has_required_fields
[Thu Apr 17 16:14:50 2014] [error]     return any(field.required for field in self.action.fields.values())
[Thu Apr 17 16:14:50 2014] [error]   File "/usr/lib/python2.7/dist-packages/horizon/workflows/base.py", line 376, in action
[Thu Apr 17 16:14:50 2014] [error]     context)
[Thu Apr 17 16:14:50 2014] [error]   File "/usr/share/openstack-dashboard/openstack_dashboard/wsgi/../../openstack_dashboard/dashboards/admin/projects/workflows.py", line 167, in __init__
[Thu Apr 17 16:14:50 2014] [error]     redirect=reverse(INDEX_URL))
[Thu Apr 17 16:14:50 2014] [error]   File "/usr/share/openstack-dashboard/openstack_dashboard/wsgi/../../openstack_dashboard/dashboards/admin/projects/workflows.py", line 163, in __init__
[Thu Apr 17 16:14:50 2014] [error]     raise exceptions.NotFound(msg)
[Thu Apr 17 16:14:50 2014] [error] NotFound: Could not find default role "Member" in Keystone
[Thu Apr 17 16:20:04 2014] [error] Creating user with name "kjas kstan"
[Thu Apr 17 16:20:05 2014] [error] Recoverable error: Conflict occurred attempting to store role grant. User 3fef801fdc884caaadda82e726edd092 already has role 9fe2ff9ee4384b1894a90878d3e92bab in tenant 82422568ec544c5e9d556a7977212b84 (HTTP 409)
[Thu Apr 17 16:20:37 2014] [error] Logging out user "admin".
[Thu Apr 17 16:20:58 2014] [error] Login successful for user "kjas kstan".
[Thu Apr 17 16:24:39 2014] [error] Logging out user "kjas kstan".
[Thu Apr 17 16:24:39 2014] [error] Could not delete token
[Thu Apr 17 16:24:49 2014] [error] Login successful for user "admin".
[Thu Apr 17 16:28:55 2014] [error] Not Found: No more floating ips available. (HTTP 404) (Request-ID: req-079613f8-a0c4-4377-9ee1-00f2d5ec28a8)
[Thu Apr 17 16:28:55 2014] [error] Traceback (most recent call last):
[Thu Apr 17 16:28:55 2014] [error]   File "/usr/share/openstack-dashboard/openstack_dashboard/wsgi/../../openstack_dashboard/dashboards/project/instances/tables.py", line 386, in single
[Thu Apr 17 16:28:55 2014] [error]     fip = api.network.tenant_floating_ip_allocate(request)
[Thu Apr 17 16:28:55 2014] [error]   File "/usr/share/openstack-dashboard/openstack_dashboard/wsgi/../../openstack_dashboard/api/network.py", line 60, in tenant_floating_ip_allocate
[Thu Apr 17 16:28:55 2014] [error]     return NetworkClient(request).floating_ips.allocate(pool)
[Thu Apr 17 16:28:55 2014] [error]   File "/usr/share/openstack-dashboard/openstack_dashboard/wsgi/../../openstack_dashboard/api/nova.py", line 331, in allocate
[Thu Apr 17 16:28:55 2014] [error]     return FloatingIp(self.client.floating_ips.create(pool=pool))
[Thu Apr 17 16:28:55 2014] [error]   File "/usr/lib/python2.7/dist-packages/novaclient/v1_1/floating_ips.py", line 41, in create
[Thu Apr 17 16:28:55 2014] [error]     return self._create("/os-floating-ips", {'pool': pool}, "floating_ip")
[Thu Apr 17 16:28:55 2014] [error]   File "/usr/lib/python2.7/dist-packages/novaclient/base.py", line 145, in _create
[Thu Apr 17 16:28:55 2014] [error]     _resp, body = self.api.client.post(url, body=body)
[Thu Apr 17 16:28:55 2014] [error]   File "/usr/lib/python2.7/dist-packages/novaclient/client.py", line 232, in post
[Thu Apr 17 16:28:55 2014] [error]     return self._cs_request(url, 'POST', **kwargs)
[Thu Apr 17 16:28:55 2014] [error]   File "/usr/lib/python2.7/dist-packages/novaclient/client.py", line 213, in _cs_request
[Thu Apr 17 16:28:55 2014] [error]     **kwargs)
[Thu Apr 17 16:28:55 2014] [error]   File "/usr/lib/python2.7/dist-packages/novaclient/client.py", line 195, in _time_request
[Thu Apr 17 16:28:55 2014] [error]     resp, body = self.request(url, method, **kwargs)
[Thu Apr 17 16:28:55 2014] [error]   File "/usr/lib/python2.7/dist-packages/novaclient/client.py", line 189, in request
[Thu Apr 17 16:28:55 2014] [error]     raise exceptions.from_response(resp, body, url, method)
[Thu Apr 17 16:28:55 2014] [error] NotFound: No more floating ips available. (HTTP 404) (Request-ID: req-079613f8-a0c4-4377-9ee1-00f2d5ec28a8)
[Thu Apr 17 16:54:57 2014] [error] Logging out user "admin".
[Thu Apr 17 17:02:13 2014] [error] [client 137.43.154.25] File does not exist: /var/www/auth
[Thu Apr 17 17:02:14 2014] [error] [client 137.43.154.25] File does not exist: /var/www/favicon.ico
[Thu Apr 17 17:02:14 2014] [error] [client 137.43.154.25] File does not exist: /var/www/favicon.ico
[Thu Apr 17 17:02:16 2014] [error] [client 137.43.154.25] File does not exist: /var/www/auth
[Thu Apr 17 17:15:14 2014] [notice] caught SIGTERM, shutting down
[Thu Apr 17 17:16:19 2014] [warn] mod_wsgi: Compiled for Python/2.7.2+.
[Thu Apr 17 17:16:19 2014] [warn] mod_wsgi: Runtime using Python/2.7.3.
[Thu Apr 17 17:16:19 2014] [notice] Apache/2.2.22 (Ubuntu) mod_wsgi/3.3 Python/2.7.3 configured -- resuming normal operations
[Thu Apr 17 18:14:53 2014] [notice] caught SIGTERM, shutting down
[Mon Apr 21 14:24:14 2014] [warn] mod_wsgi: Compiled for Python/2.7.2+.
[Mon Apr 21 14:24:14 2014] [warn] mod_wsgi: Runtime using Python/2.7.3.
[Mon Apr 21 14:24:14 2014] [notice] Apache/2.2.22 (Ubuntu) mod_wsgi/3.3 Python/2.7.3 configured -- resuming normal operations
[Mon Apr 21 14:38:13 2014] [notice] caught SIGTERM, shutting down
[Mon Apr 21 14:41:08 2014] [warn] mod_wsgi: Compiled for Python/2.7.2+.
[Mon Apr 21 14:41:08 2014] [warn] mod_wsgi: Runtime using Python/2.7.3.
[Mon Apr 21 14:41:08 2014] [notice] Apache/2.2.22 (Ubuntu) mod_wsgi/3.3 Python/2.7.3 configured -- resuming normal operations
[Mon Apr 21 14:48:24 2014] [notice] caught SIGTERM, shutting down
[Mon Apr 21 14:49:29 2014] [warn] mod_wsgi: Compiled for Python/2.7.2+.
[Mon Apr 21 14:49:29 2014] [warn] mod_wsgi: Runtime using Python/2.7.3.
[Mon Apr 21 14:49:29 2014] [notice] Apache/2.2.22 (Ubuntu) mod_wsgi/3.3 Python/2.7.3 configured -- resuming normal operations
[Mon Apr 21 14:53:45 2014] [notice] caught SIGTERM, shutting down
[Mon Apr 21 14:54:50 2014] [warn] mod_wsgi: Compiled for Python/2.7.2+.
[Mon Apr 21 14:54:50 2014] [warn] mod_wsgi: Runtime using Python/2.7.3.
[Mon Apr 21 14:54:50 2014] [notice] Apache/2.2.22 (Ubuntu) mod_wsgi/3.3 Python/2.7.3 configured -- resuming normal operations
[Mon Apr 21 15:01:02 2014] [error] Login successful for user "admin".
[Mon Apr 21 15:02:49 2014] [error] Agendada a finaliza\xc3\xa7\xc3\xa3o de Inst\xc3\xa2ncia: "ttytest8"
[Mon Apr 21 15:02:50 2014] [error] Agendada a finaliza\xc3\xa7\xc3\xa3o de Inst\xc3\xa2ncia: "ttytest7"
[Mon Apr 21 15:02:50 2014] [error] Agendada a finaliza\xc3\xa7\xc3\xa3o de Inst\xc3\xa2ncia: "ttytest6"
[Mon Apr 21 15:02:50 2014] [error] Agendada a finaliza\xc3\xa7\xc3\xa3o de Inst\xc3\xa2ncia: "ttytest5"
[Mon Apr 21 15:02:51 2014] [error] Agendada a finaliza\xc3\xa7\xc3\xa3o de Inst\xc3\xa2ncia: "ttytest4"
[Mon Apr 21 15:02:51 2014] [error] Agendada a finaliza\xc3\xa7\xc3\xa3o de Inst\xc3\xa2ncia: "ttytest3"
[Mon Apr 21 15:02:51 2014] [error] Agendada a finaliza\xc3\xa7\xc3\xa3o de Inst\xc3\xa2ncia: "ttytest2"
[Mon Apr 21 15:02:52 2014] [error] Agendada a finaliza\xc3\xa7\xc3\xa3o de Inst\xc3\xa2ncia: "ttytest1"
[Mon Apr 21 15:02:52 2014] [error] Agendada a finaliza\xc3\xa7\xc3\xa3o de Inst\xc3\xa2ncia: "dfire_test3"
[Mon Apr 21 15:02:53 2014] [error] Agendada a finaliza\xc3\xa7\xc3\xa3o de Inst\xc3\xa2ncia: "dfire_test2"
[Mon Apr 21 15:06:54 2014] [error] Login failed for user "admin".
[Mon Apr 21 15:07:03 2014] [error] Login successful for user "admin".
[Mon Apr 21 15:09:05 2014] [error] Creating user with name "animall"
[Mon Apr 21 15:09:05 2014] [error] Recoverable error: Conflict occurred attempting to store role grant. User 253f4b4150a94040ac288bf8fd0dfea7 already has role 9fe2ff9ee4384b1894a90878d3e92bab in tenant 300407136d2840659371f14b92114e44 (HTTP 409)
[Mon Apr 21 15:10:22 2014] [error] Creating user with name "macos"
[Mon Apr 21 15:10:23 2014] [error] Recoverable error: Conflict occurred attempting to store role grant. User 61b3f2a57e3041fa9cc956408bf2433b already has role 9fe2ff9ee4384b1894a90878d3e92bab in tenant 07a6e4f8ae5640b7b1a4e8aed225bbbf (HTTP 409)
[Mon Apr 21 15:11:03 2014] [error] Creating user with name "helipadsales"
[Mon Apr 21 15:11:03 2014] [error] Recoverable error: Conflict occurred attempting to store role grant. User 847707c76b4940a99a221a3ce4f2dce4 already has role 9fe2ff9ee4384b1894a90878d3e92bab in tenant 6ecdc00b0bd74b648aea1ba538e60218 (HTTP 409)
[Mon Apr 21 15:11:42 2014] [error] Creating user with name "ubishaft"
[Mon Apr 21 15:11:43 2014] [error] Recoverable error: Conflict occurred attempting to store role grant. User ab9892d9cb7e40078be899c34c20b020 already has role 9fe2ff9ee4384b1894a90878d3e92bab in tenant 2c45fb26257b44aab3b20e0e78964637 (HTTP 409)
[Mon Apr 21 15:12:17 2014] [error] Creating user with name "frikandelfun"
[Mon Apr 21 15:12:17 2014] [error] Recoverable error: Conflict occurred attempting to store role grant. User 2c159dbdd4ba4f1587ecd502afbe1fe1 already has role 9fe2ff9ee4384b1894a90878d3e92bab in tenant 7f160df0521b4c5b87783b52c9184b3c (HTTP 409)
[Mon Apr 21 15:12:49 2014] [error] Creating user with name "silkpath"
[Mon Apr 21 15:12:49 2014] [error] Recoverable error: Conflict occurred attempting to store role grant. User 90dfd53b7d924654bff1f78d81591766 already has role 9fe2ff9ee4384b1894a90878d3e92bab in tenant eb7353fee31e4c45a9e82742b3a9a9e3 (HTTP 409)
[Mon Apr 21 15:13:19 2014] [error] Logging out user "admin".
[Mon Apr 21 15:13:26 2014] [error] Logging out user "admin".
[Mon Apr 21 15:13:56 2014] [error] Login successful for user "animall".
[Mon Apr 21 15:14:13 2014] [error] Login successful for user "ubishaft".
[Mon Apr 21 15:19:23 2014] [error] Logging out user "animall".
[Mon Apr 21 15:19:23 2014] [error] Could not delete token
[Mon Apr 21 15:19:31 2014] [error] Login successful for user "macos".
[Mon Apr 21 15:20:10 2014] [error] Logging out user "ubishaft".
[Mon Apr 21 15:20:10 2014] [error] Could not delete token
[Mon Apr 21 15:20:34 2014] [error] Login successful for user "frikandelfun".
[Mon Apr 21 15:20:53 2014] [error] Logging out user "macos".
[Mon Apr 21 15:20:54 2014] [error] Could not delete token
[Mon Apr 21 15:21:08 2014] [error] Login successful for user "helipadsales".
[Mon Apr 21 15:22:18 2014] [error] Logging out user "helipadsales".
[Mon Apr 21 15:22:18 2014] [error] Could not delete token
[Mon Apr 21 15:22:28 2014] [error] Login successful for user "admin".
[Mon Apr 21 15:23:08 2014] [error] Logging out user "frikandelfun".
[Mon Apr 21 15:23:08 2014] [error] Could not delete token
[Mon Apr 21 15:23:19 2014] [error] Login successful for user "silkpath".
[Mon Apr 21 15:25:47 2014] [error] Logging out user "silkpath".
[Mon Apr 21 15:25:47 2014] [error] Could not delete token
[Mon Apr 21 15:26:05 2014] [error] Scheduled termination of Instance: "market"
[Mon Apr 21 15:26:08 2014] [error] Login successful for user "admin".
[Mon Apr 21 15:26:34 2014] [error] Scheduled termination of Instance: "market"
[Mon Apr 21 15:26:35 2014] [error] Scheduled termination of Instance: "shop"
[Mon Apr 21 15:27:15 2014] [error] Soft Rebooted Instance: "kj1"
[Mon Apr 21 15:27:57 2014] [error] Logging out user "admin".
[Mon Apr 21 15:28:10 2014] [error] Login successful for user "macos".
[Mon Apr 21 15:28:27 2014] [error] Logging out user "admin".
[Mon Apr 21 15:28:39 2014] [error] Login successful for user "silkpath".
[Mon Apr 21 15:29:12 2014] [error] Logging out user "macos".
[Mon Apr 21 15:29:12 2014] [error] Could not delete token
[Mon Apr 21 15:29:30 2014] [error] Login failed for user "kjas kstan".
[Mon Apr 21 15:29:36 2014] [error] Logging out user "silkpath".
[Mon Apr 21 15:29:36 2014] [error] Could not delete token
[Mon Apr 21 15:29:46 2014] [error] Login failed for user "kjas kistan".
[Mon Apr 21 15:29:47 2014] [error] Login successful for user "frikandelfun".
[Mon Apr 21 15:29:58 2014] [error] Login successful for user "admin".
[Mon Apr 21 15:30:47 2014] [error] Logging out user "frikandelfun".
[Mon Apr 21 15:30:47 2014] [error] Could not delete token
[Mon Apr 21 15:31:05 2014] [error] Login successful for user "ubishaft".
[Mon Apr 21 15:32:23 2014] [error] Logging out user "ubishaft".
[Mon Apr 21 15:32:23 2014] [error] Could not delete token
[Mon Apr 21 15:32:37 2014] [error] Login successful for user "admin".
[Mon Apr 21 15:34:02 2014] [error] Logging out user "admin".
[Mon Apr 21 15:34:13 2014] [error] Login successful for user "macos".
[Mon Apr 21 15:41:57 2014] [notice] caught SIGTERM, shutting down
[Mon Apr 21 15:43:04 2014] [warn] mod_wsgi: Compiled for Python/2.7.2+.
[Mon Apr 21 15:43:04 2014] [warn] mod_wsgi: Runtime using Python/2.7.3.
[Mon Apr 21 15:43:04 2014] [notice] Apache/2.2.22 (Ubuntu) mod_wsgi/3.3 Python/2.7.3 configured -- resuming normal operations
[Mon Apr 21 15:49:02 2014] [error] Logging out user "macos".
[Mon Apr 21 15:49:02 2014] [error] Could not delete token
[Mon Apr 21 15:49:30 2014] [error] Login successful for user "admin".
[Mon Apr 21 15:50:32 2014] [error] Logging out user "admin".
[Mon Apr 21 15:55:17 2014] [notice] caught SIGTERM, shutting down
[Mon Apr 21 15:56:25 2014] [warn] mod_wsgi: Compiled for Python/2.7.2+.
[Mon Apr 21 15:56:25 2014] [warn] mod_wsgi: Runtime using Python/2.7.3.
[Mon Apr 21 15:56:25 2014] [notice] Apache/2.2.22 (Ubuntu) mod_wsgi/3.3 Python/2.7.3 configured -- resuming normal operations
[Mon Apr 21 15:58:46 2014] [error] Login successful for user "admin".
[Mon Apr 21 16:01:16 2014] [error] Logging out user "admin".
[Mon Apr 21 16:01:22 2014] [error] Login successful for user "macos".
[Mon Apr 21 16:02:51 2014] [error] Recoverable error: The supplied device path (/dev/sda) is in use. (HTTP 409) (Request-ID: req-daea5c73-b568-496d-b505-d7e4046fb812)
[Mon Apr 21 16:04:31 2014] [error] Logging out user "admin".
[Mon Apr 21 16:04:42 2014] [error] Login successful for user "macos".
[Mon Apr 21 16:06:23 2014] [error] [client 192.168.0.5] File does not exist: /var/www/horizeon
[Mon Apr 21 16:06:23 2014] [error] [client 192.168.0.5] File does not exist: /var/www/favicon.ico
[Mon Apr 21 16:25:16 2014] [error] Logging out user "macos".
[Mon Apr 21 16:25:16 2014] [error] Could not delete token
[Mon Apr 21 16:25:25 2014] [error] Login successful for user "admin".
[Mon Apr 21 16:26:16 2014] [error] Scheduled termination of Instance: "bootable3"
[Mon Apr 21 16:26:16 2014] [error] Scheduled termination of Instance: "bootable1"
[Mon Apr 21 16:26:16 2014] [error] Scheduled termination of Instance: "bootable"
[Mon Apr 21 16:29:26 2014] [error] Scheduled termination of Instance: "bootable3"
[Mon Apr 21 16:31:43 2014] [error] Logging out user "macos".
[Mon Apr 21 16:31:43 2014] [error] Could not delete token
[Mon Apr 21 16:31:57 2014] [error] Login successful for user "admin".
[Mon Apr 21 16:41:40 2014] [error] Suspended Instance: "small"
[Mon Apr 21 16:42:49 2014] [error] Suspended Instance: "bootable3"
[Mon Apr 21 16:42:51 2014] [error] Suspended Instance: "agin"
[Mon Apr 21 16:42:53 2014] [error] Suspended Instance: "Imback"
[Mon Apr 21 16:42:55 2014] [error] Suspended Instance: "onemore"
[Mon Apr 21 16:43:12 2014] [error] Suspended Instance: "Backup"
[Mon Apr 21 16:43:21 2014] [error] Suspended Instance: "sundaymarket"
[Mon Apr 21 16:43:24 2014] [error] Suspended Instance: "centremarkrt"
[Mon Apr 21 16:43:26 2014] [error] Suspended Instance: "shop"
[Mon Apr 21 16:43:29 2014] [error] Suspended Instance: "hellothere"
[Mon Apr 21 16:43:44 2014] [error] Suspended Instance: "intern"
[Mon Apr 21 16:43:45 2014] [error] Suspended Instance: "wehere"
[Mon Apr 21 16:43:47 2014] [error] Suspended Instance: "manager"
[Mon Apr 21 16:43:50 2014] [error] Suspended Instance: "boss"
[Mon Apr 21 16:43:52 2014] [error] Suspended Instance: "findus"
[Mon Apr 21 16:44:08 2014] [error] Suspended Instance: "KB"
[Mon Apr 21 16:44:10 2014] [error] Suspended Instance: "Q&A"
[Mon Apr 21 16:44:12 2014] [error] Suspended Instance: "SAC"
[Mon Apr 21 16:44:14 2014] [error] Suspended Instance: "healthcentre"
[Mon Apr 21 16:44:29 2014] [error] Suspended Instance: "controller"
[Mon Apr 21 16:46:17 2014] [error] Logging out user "admin".
[Mon Apr 21 16:46:27 2014] [error] Login successful for user "ubishaft".
[Mon Apr 21 16:46:48 2014] [error] Suspended Instance: "shopping"
[Mon Apr 21 16:46:54 2014] [error] Suspended Instance: "market"
[Mon Apr 21 16:47:03 2014] [error] Logging out user "ubishaft".
[Mon Apr 21 16:47:03 2014] [error] Could not delete token
[Mon Apr 21 16:47:10 2014] [error] Login failed for user "admin".
[Mon Apr 21 16:47:21 2014] [error] Login failed for user "admin".
[Mon Apr 21 16:47:22 2014] [error] Logging out user "admin".
[Mon Apr 21 16:47:31 2014] [error] Login successful for user "silkpath".
[Mon Apr 21 16:47:31 2014] [error] Login successful for user "admin".
[Mon Apr 21 16:47:54 2014] [error] Logging out user "admin".
[Mon Apr 21 16:48:05 2014] [error] Login successful for user "animall".
[Mon Apr 21 16:48:22 2014] [error] Suspended Instance: "Backup shop"
[Mon Apr 21 16:48:29 2014] [error] Suspended Instance: "shop2"
[Mon Apr 21 16:48:34 2014] [error] Logging out user "animall".
[Mon Apr 21 16:48:34 2014] [error] Could not delete token
[Mon Apr 21 16:53:22 2014] [error] Login failed for user "admin".
[Mon Apr 21 16:53:30 2014] [error] Login successful for user "admin".
[Mon Apr 21 16:54:31 2014] [error] Scheduled termination of Instance: "small"
[Mon Apr 21 17:01:20 2014] [error] Scheduled termination of Instance: "fucklarge-9d47eb30-4026-4a8b-b34a-4770d74f51e2"
[Mon Apr 21 17:01:20 2014] [error] Scheduled termination of Instance: "fucklarge-4114c4cb-fe04-478f-af91-20eab2b0e560"
[Mon Apr 21 17:06:04 2014] [error] Scheduled termination of Instance: "notthathard"
[Mon Apr 21 17:06:04 2014] [error] Scheduled termination of Instance: "small3"
[Mon Apr 21 17:06:04 2014] [error] Scheduled termination of Instance: "small2"
[Mon Apr 21 17:06:05 2014] [error] Scheduled termination of Instance: "bootable3"
[Mon Apr 21 17:06:05 2014] [error] Scheduled termination of Instance: "agin"
[Mon Apr 21 17:06:05 2014] [error] Scheduled termination of Instance: "Imback"
[Mon Apr 21 17:06:06 2014] [error] Scheduled termination of Instance: "onemore"
[Mon Apr 21 17:06:06 2014] [error] Scheduled termination of Instance: "Backup"
[Mon Apr 21 17:06:07 2014] [error] Scheduled termination of Instance: "sundaymarket"
[Mon Apr 21 17:06:07 2014] [error] Scheduled termination of Instance: "centremarkrt"
[Mon Apr 21 17:06:07 2014] [error] Scheduled termination of Instance: "shop"
[Mon Apr 21 17:06:08 2014] [error] Scheduled termination of Instance: "hellothere"
[Mon Apr 21 17:06:08 2014] [error] Scheduled termination of Instance: "intern"
[Mon Apr 21 17:06:08 2014] [error] Scheduled termination of Instance: "wehere"
[Mon Apr 21 17:06:09 2014] [error] Scheduled termination of Instance: "manager"
[Mon Apr 21 17:06:09 2014] [error] Scheduled termination of Instance: "boss"
[Mon Apr 21 17:06:10 2014] [error] Scheduled termination of Instance: "findus"
[Mon Apr 21 17:06:10 2014] [error] Scheduled termination of Instance: "KB"
[Mon Apr 21 17:06:10 2014] [error] Scheduled termination of Instance: "Q&A"
[Mon Apr 21 17:06:11 2014] [error] Scheduled termination of Instance: "SAC"
[Mon Apr 21 17:06:39 2014] [error] Scheduled termination of Instance: "healthcentre"
[Mon Apr 21 17:27:32 2014] [error] Scheduled termination of Instance: "sshtest"
[Mon Apr 21 17:31:16 2014] [error] [client 192.168.0.4] File does not exist: /var/www/favicon.ico
[Mon Apr 21 17:31:16 2014] [error] [client 192.168.0.4] File does not exist: /var/www/favicon.ico
[Mon Apr 21 17:40:28 2014] [error] Scheduled termination of Instance: "sshtest2"
[Mon Apr 21 17:40:28 2014] [error] Scheduled termination of Instance: "sshtest"
[Mon Apr 21 17:59:25 2014] [error] Logging out user "admin".
[Tue Apr 22 08:49:48 2014] [error] Login successful for user "admin".
[Tue Apr 22 08:51:19 2014] [error] Scheduled termination of Instance: "controller"
[Tue Apr 22 08:51:19 2014] [error] Scheduled termination of Instance: "shopping"
[Tue Apr 22 08:51:20 2014] [error] Scheduled termination of Instance: "Backup shop"
[Tue Apr 22 08:51:20 2014] [error] Scheduled termination of Instance: "market"
[Tue Apr 22 08:51:20 2014] [error] Scheduled termination of Instance: "shop2"
[Tue Apr 22 08:51:21 2014] [error] Scheduled termination of Instance: "kj1"
[Tue Apr 22 09:33:28 2014] [error] Scheduled termination of Instance: "iptest"
[Tue Apr 22 09:34:58 2014] [error] Not Found: No more floating ips available. (HTTP 404) (Request-ID: req-c8400243-c1e8-4ad0-a583-5f4332cbd388)
[Tue Apr 22 09:34:58 2014] [error] Traceback (most recent call last):
[Tue Apr 22 09:34:58 2014] [error]   File "/usr/share/openstack-dashboard/openstack_dashboard/wsgi/../../openstack_dashboard/dashboards/project/instances/tables.py", line 386, in single
[Tue Apr 22 09:34:58 2014] [error]     fip = api.network.tenant_floating_ip_allocate(request)
[Tue Apr 22 09:34:58 2014] [error]   File "/usr/share/openstack-dashboard/openstack_dashboard/wsgi/../../openstack_dashboard/api/network.py", line 60, in tenant_floating_ip_allocate
[Tue Apr 22 09:34:58 2014] [error]     return NetworkClient(request).floating_ips.allocate(pool)
[Tue Apr 22 09:34:58 2014] [error]   File "/usr/share/openstack-dashboard/openstack_dashboard/wsgi/../../openstack_dashboard/api/nova.py", line 331, in allocate
[Tue Apr 22 09:34:58 2014] [error]     return FloatingIp(self.client.floating_ips.create(pool=pool))
[Tue Apr 22 09:34:58 2014] [error]   File "/usr/lib/python2.7/dist-packages/novaclient/v1_1/floating_ips.py", line 41, in create
[Tue Apr 22 09:34:58 2014] [error]     return self._create("/os-floating-ips", {'pool': pool}, "floating_ip")
[Tue Apr 22 09:34:58 2014] [error]   File "/usr/lib/python2.7/dist-packages/novaclient/base.py", line 145, in _create
[Tue Apr 22 09:34:58 2014] [error]     _resp, body = self.api.client.post(url, body=body)
[Tue Apr 22 09:34:58 2014] [error]   File "/usr/lib/python2.7/dist-packages/novaclient/client.py", line 232, in post
[Tue Apr 22 09:34:58 2014] [error]     return self._cs_request(url, 'POST', **kwargs)
[Tue Apr 22 09:34:58 2014] [error]   File "/usr/lib/python2.7/dist-packages/novaclient/client.py", line 213, in _cs_request
[Tue Apr 22 09:34:58 2014] [error]     **kwargs)
[Tue Apr 22 09:34:58 2014] [error]   File "/usr/lib/python2.7/dist-packages/novaclient/client.py", line 195, in _time_request
[Tue Apr 22 09:34:58 2014] [error]     resp, body = self.request(url, method, **kwargs)
[Tue Apr 22 09:34:58 2014] [error]   File "/usr/lib/python2.7/dist-packages/novaclient/client.py", line 189, in request
[Tue Apr 22 09:34:58 2014] [error]     raise exceptions.from_response(resp, body, url, method)
[Tue Apr 22 09:34:58 2014] [error] NotFound: No more floating ips available. (HTTP 404) (Request-ID: req-c8400243-c1e8-4ad0-a583-5f4332cbd388)
[Tue Apr 22 10:05:16 2014] [error] Failed to retrieve quota information
[Tue Apr 22 10:05:16 2014] [error] Traceback (most recent call last):
[Tue Apr 22 10:05:16 2014] [error]   File "/usr/share/openstack-dashboard/openstack_dashboard/wsgi/../../openstack_dashboard/dashboards/project/instances/tables.py", line 189, in allowed
[Tue Apr 22 10:05:16 2014] [error]     limits = api.nova.tenant_absolute_limits(request, reserved=True)
[Tue Apr 22 10:05:16 2014] [error]   File "/usr/share/openstack-dashboard/openstack_dashboard/wsgi/../../openstack_dashboard/api/nova.py", line 652, in tenant_absolute_limits
[Tue Apr 22 10:05:16 2014] [error]     limits = novaclient(request).limits.get(reserved=reserved).absolute
[Tue Apr 22 10:05:16 2014] [error]   File "/usr/lib/python2.7/dist-packages/novaclient/v1_1/limits.py", line 87, in get
[Tue Apr 22 10:05:16 2014] [error]     return self._get("/limits%s" % query_string, "limits")
[Tue Apr 22 10:05:16 2014] [error]   File "/usr/lib/python2.7/dist-packages/novaclient/base.py", line 140, in _get
[Tue Apr 22 10:05:16 2014] [error]     _resp, body = self.api.client.get(url)
[Tue Apr 22 10:05:16 2014] [error]   File "/usr/lib/python2.7/dist-packages/novaclient/client.py", line 229, in get
[Tue Apr 22 10:05:16 2014] [error]     return self._cs_request(url, 'GET', **kwargs)
[Tue Apr 22 10:05:16 2014] [error]   File "/usr/lib/python2.7/dist-packages/novaclient/client.py", line 213, in _cs_request
[Tue Apr 22 10:05:16 2014] [error]     **kwargs)
[Tue Apr 22 10:05:16 2014] [error]   File "/usr/lib/python2.7/dist-packages/novaclient/client.py", line 195, in _time_request
[Tue Apr 22 10:05:16 2014] [error]     resp, body = self.request(url, method, **kwargs)
[Tue Apr 22 10:05:16 2014] [error]   File "/usr/lib/python2.7/dist-packages/novaclient/client.py", line 166, in request
[Tue Apr 22 10:05:16 2014] [error]     **kwargs)
[Tue Apr 22 10:05:16 2014] [error]   File "/usr/lib/python2.7/dist-packages/requests/sessions.py", line 335, in request
[Tue Apr 22 10:05:16 2014] [error]     resp = self.send(prep, **send_kwargs)
[Tue Apr 22 10:05:16 2014] [error]   File "/usr/lib/python2.7/dist-packages/requests/sessions.py", line 438, in send
[Tue Apr 22 10:05:16 2014] [error]     r = adapter.send(request, **kwargs)
[Tue Apr 22 10:05:16 2014] [error]   File "/usr/lib/python2.7/dist-packages/requests/adapters.py", line 327, in send
[Tue Apr 22 10:05:16 2014] [error]     raise ConnectionError(e)
[Tue Apr 22 10:05:16 2014] [error] ConnectionError: HTTPConnectionPool(host='csi', port=8774): Max retries exceeded with url: /v2/e7dcfe9fe2f143d29e518e41a20553cf/limits?reserved=1 (Caused by <class 'socket.error'>: [Errno 104] Connection reset by peer)
[Tue Apr 22 10:05:16 2014] [error] Internal Server Error: /horizon/project/instances/
[Tue Apr 22 10:05:16 2014] [error] Traceback (most recent call last):
[Tue Apr 22 10:05:16 2014] [error]   File "/usr/lib/python2.7/dist-packages/django/core/handlers/base.py", line 115, in get_response
[Tue Apr 22 10:05:16 2014] [error]     response = callback(request, *callback_args, **callback_kwargs)
[Tue Apr 22 10:05:16 2014] [error]   File "/usr/lib/python2.7/dist-packages/horizon/decorators.py", line 38, in dec
[Tue Apr 22 10:05:16 2014] [error]     return view_func(request, *args, **kwargs)
[Tue Apr 22 10:05:16 2014] [error]   File "/usr/lib/python2.7/dist-packages/horizon/decorators.py", line 54, in dec
[Tue Apr 22 10:05:16 2014] [error]     return view_func(request, *args, **kwargs)
[Tue Apr 22 10:05:16 2014] [error]   File "/usr/lib/python2.7/dist-packages/horizon/decorators.py", line 38, in dec
[Tue Apr 22 10:05:16 2014] [error]     return view_func(request, *args, **kwargs)
[Tue Apr 22 10:05:16 2014] [error]   File "/usr/lib/python2.7/dist-packages/django/views/generic/base.py", line 68, in view
[Tue Apr 22 10:05:16 2014] [error]     return self.dispatch(request, *args, **kwargs)
[Tue Apr 22 10:05:16 2014] [error]   File "/usr/lib/python2.7/dist-packages/django/views/generic/base.py", line 86, in dispatch
[Tue Apr 22 10:05:16 2014] [error]     return handler(request, *args, **kwargs)
[Tue Apr 22 10:05:16 2014] [error]   File "/usr/lib/python2.7/dist-packages/horizon/tables/views.py", line 155, in get
[Tue Apr 22 10:05:16 2014] [error]     handled = self.construct_tables()
[Tue Apr 22 10:05:16 2014] [error]   File "/usr/lib/python2.7/dist-packages/horizon/tables/views.py", line 146, in construct_tables
[Tue Apr 22 10:05:16 2014] [error]     handled = self.handle_table(table)
[Tue Apr 22 10:05:16 2014] [error]   File "/usr/lib/python2.7/dist-packages/horizon/tables/views.py", line 118, in handle_table
[Tue Apr 22 10:05:16 2014] [error]     data = self._get_data_dict()
[Tue Apr 22 10:05:16 2014] [error]   File "/usr/lib/python2.7/dist-packages/horizon/tables/views.py", line 182, in _get_data_dict
[Tue Apr 22 10:05:16 2014] [error]     self._data = {self.table_class._meta.name: self.get_data()}
[Tue Apr 22 10:05:16 2014] [error]   File "/usr/share/openstack-dashboard/openstack_dashboard/wsgi/../../openstack_dashboard/dashboards/project/instances/views.py", line 68, in get_data
[Tue Apr 22 10:05:16 2014] [error]     _('Unable to retrieve instances.'))
[Tue Apr 22 10:05:16 2014] [error]   File "/usr/share/openstack-dashboard/openstack_dashboard/wsgi/../../openstack_dashboard/dashboards/project/instances/views.py", line 63, in get_data
[Tue Apr 22 10:05:16 2014] [error]     'paginate': True})
[Tue Apr 22 10:05:16 2014] [error]   File "/usr/share/openstack-dashboard/openstack_dashboard/wsgi/../../openstack_dashboard/api/nova.py", line 509, in server_list
[Tue Apr 22 10:05:16 2014] [error]     for s in novaclient(request).servers.list(True, search_opts)]
[Tue Apr 22 10:05:16 2014] [error]   File "/usr/lib/python2.7/dist-packages/novaclient/v1_1/servers.py", line 404, in list
[Tue Apr 22 10:05:16 2014] [error]     return self._list("/servers%s%s" % (detail, query_string), "servers")
[Tue Apr 22 10:05:16 2014] [error]   File "/usr/lib/python2.7/dist-packages/novaclient/base.py", line 61, in _list
[Tue Apr 22 10:05:16 2014] [error]     _resp, body = self.api.client.get(url)
[Tue Apr 22 10:05:16 2014] [error]   File "/usr/lib/python2.7/dist-packages/novaclient/client.py", line 229, in get
[Tue Apr 22 10:05:16 2014] [error]     return self._cs_request(url, 'GET', **kwargs)
[Tue Apr 22 10:05:16 2014] [error]   File "/usr/lib/python2.7/dist-packages/novaclient/client.py", line 213, in _cs_request
[Tue Apr 22 10:05:16 2014] [error]     **kwargs)
[Tue Apr 22 10:05:16 2014] [error]   File "/usr/lib/python2.7/dist-packages/novaclient/client.py", line 195, in _time_request
[Tue Apr 22 10:05:16 2014] [error]     resp, body = self.request(url, method, **kwargs)
[Tue Apr 22 10:05:16 2014] [error]   File "/usr/lib/python2.7/dist-packages/novaclient/client.py", line 166, in request
[Tue Apr 22 10:05:16 2014] [error]     **kwargs)
[Tue Apr 22 10:05:16 2014] [error]   File "/usr/lib/python2.7/dist-packages/requests/sessions.py", line 335, in request
[Tue Apr 22 10:05:16 2014] [error]     resp = self.send(prep, **send_kwargs)
[Tue Apr 22 10:05:16 2014] [error]   File "/usr/lib/python2.7/dist-packages/requests/sessions.py", line 438, in send
[Tue Apr 22 10:05:16 2014] [error]     r = adapter.send(request, **kwargs)
[Tue Apr 22 10:05:16 2014] [error]   File "/usr/lib/python2.7/dist-packages/requests/adapters.py", line 327, in send
[Tue Apr 22 10:05:16 2014] [error]     raise ConnectionError(e)
[Tue Apr 22 10:05:16 2014] [error] ConnectionError: HTTPConnectionPool(host='csi', port=8774): Max retries exceeded with url: /v2/e7dcfe9fe2f143d29e518e41a20553cf/servers/detail?project_id=e7dcfe9fe2f143d29e518e41a20553cf&limit=21 (Caused by <class 'socket.error'>: [Errno 104] Connection reset by peer)
[Tue Apr 22 10:05:16 2014] [error] Internal Server Error: /horizon/project/instances/
[Tue Apr 22 10:05:16 2014] [error] Traceback (most recent call last):
[Tue Apr 22 10:05:16 2014] [error]   File "/usr/lib/python2.7/dist-packages/django/core/handlers/base.py", line 115, in get_response
[Tue Apr 22 10:05:16 2014] [error]     response = callback(request, *callback_args, **callback_kwargs)
[Tue Apr 22 10:05:16 2014] [error]   File "/usr/lib/python2.7/dist-packages/horizon/decorators.py", line 38, in dec
[Tue Apr 22 10:05:16 2014] [error]     return view_func(request, *args, **kwargs)
[Tue Apr 22 10:05:16 2014] [error]   File "/usr/lib/python2.7/dist-packages/horizon/decorators.py", line 54, in dec
[Tue Apr 22 10:05:16 2014] [error]     return view_func(request, *args, **kwargs)
[Tue Apr 22 10:05:16 2014] [error]   File "/usr/lib/python2.7/dist-packages/horizon/decorators.py", line 38, in dec
[Tue Apr 22 10:05:16 2014] [error]     return view_func(request, *args, **kwargs)
[Tue Apr 22 10:05:16 2014] [error]   File "/usr/lib/python2.7/dist-packages/django/views/generic/base.py", line 68, in view
[Tue Apr 22 10:05:16 2014] [error]     return self.dispatch(request, *args, **kwargs)
[Tue Apr 22 10:05:16 2014] [error]   File "/usr/lib/python2.7/dist-packages/django/views/generic/base.py", line 86, in dispatch
[Tue Apr 22 10:05:16 2014] [error]     return handler(request, *args, **kwargs)
[Tue Apr 22 10:05:16 2014] [error]   File "/usr/lib/python2.7/dist-packages/horizon/tables/views.py", line 155, in get
[Tue Apr 22 10:05:16 2014] [error]     handled = self.construct_tables()
[Tue Apr 22 10:05:16 2014] [error]   File "/usr/lib/python2.7/dist-packages/horizon/tables/views.py", line 146, in construct_tables
[Tue Apr 22 10:05:16 2014] [error]     handled = self.handle_table(table)
[Tue Apr 22 10:05:16 2014] [error]   File "/usr/lib/python2.7/dist-packages/horizon/tables/views.py", line 118, in handle_table
[Tue Apr 22 10:05:16 2014] [error]     data = self._get_data_dict()
[Tue Apr 22 10:05:16 2014] [error]   File "/usr/lib/python2.7/dist-packages/horizon/tables/views.py", line 182, in _get_data_dict
[Tue Apr 22 10:05:16 2014] [error]     self._data = {self.table_class._meta.name: self.get_data()}
[Tue Apr 22 10:05:16 2014] [error]   File "/usr/share/openstack-dashboard/openstack_dashboard/wsgi/../../openstack_dashboard/dashboards/project/instances/views.py", line 68, in get_data
[Tue Apr 22 10:05:16 2014] [error]     _('Unable to retrieve instances.'))
[Tue Apr 22 10:05:16 2014] [error]   File "/usr/share/openstack-dashboard/openstack_dashboard/wsgi/../../openstack_dashboard/dashboards/project/instances/views.py", line 63, in get_data
[Tue Apr 22 10:05:16 2014] [error]     'paginate': True})
[Tue Apr 22 10:05:16 2014] [error]   File "/usr/share/openstack-dashboard/openstack_dashboard/wsgi/../../openstack_dashboard/api/nova.py", line 509, in server_list
[Tue Apr 22 10:05:16 2014] [error]     for s in novaclient(request).servers.list(True, search_opts)]
[Tue Apr 22 10:05:16 2014] [error]   File "/usr/lib/python2.7/dist-packages/novaclient/v1_1/servers.py", line 404, in list
[Tue Apr 22 10:05:16 2014] [error]     return self._list("/servers%s%s" % (detail, query_string), "servers")
[Tue Apr 22 10:05:16 2014] [error]   File "/usr/lib/python2.7/dist-packages/novaclient/base.py", line 61, in _list
[Tue Apr 22 10:05:16 2014] [error]     _resp, body = self.api.client.get(url)
[Tue Apr 22 10:05:16 2014] [error]   File "/usr/lib/python2.7/dist-packages/novaclient/client.py", line 229, in get
[Tue Apr 22 10:05:16 2014] [error]     return self._cs_request(url, 'GET', **kwargs)
[Tue Apr 22 10:05:16 2014] [error]   File "/usr/lib/python2.7/dist-packages/novaclient/client.py", line 213, in _cs_request
[Tue Apr 22 10:05:16 2014] [error]     **kwargs)
[Tue Apr 22 10:05:16 2014] [error]   File "/usr/lib/python2.7/dist-packages/novaclient/client.py", line 195, in _time_request
[Tue Apr 22 10:05:16 2014] [error]     resp, body = self.request(url, method, **kwargs)
[Tue Apr 22 10:05:16 2014] [error]   File "/usr/lib/python2.7/dist-packages/novaclient/client.py", line 166, in request
[Tue Apr 22 10:05:16 2014] [error]     **kwargs)
[Tue Apr 22 10:05:16 2014] [error]   File "/usr/lib/python2.7/dist-packages/requests/sessions.py", line 335, in request
[Tue Apr 22 10:05:16 2014] [error]     resp = self.send(prep, **send_kwargs)
[Tue Apr 22 10:05:16 2014] [error]   File "/usr/lib/python2.7/dist-packages/requests/sessions.py", line 438, in send
[Tue Apr 22 10:05:16 2014] [error]     r = adapter.send(request, **kwargs)
[Tue Apr 22 10:05:16 2014] [error]   File "/usr/lib/python2.7/dist-packages/requests/adapters.py", line 327, in send
[Tue Apr 22 10:05:16 2014] [error]     raise ConnectionError(e)
[Tue Apr 22 10:05:16 2014] [error] ConnectionError: HTTPConnectionPool(host='csi', port=8774): Max retries exceeded with url: /v2/e7dcfe9fe2f143d29e518e41a20553cf/servers/detail?project_id=e7dcfe9fe2f143d29e518e41a20553cf&limit=21 (Caused by <class 'socket.error'>: [Errno 104] Connection reset by peer)
[Tue Apr 22 10:05:17 2014] [error] Internal Server Error: /horizon/admin/
[Tue Apr 22 10:05:17 2014] [error] Traceback (most recent call last):
[Tue Apr 22 10:05:17 2014] [error]   File "/usr/lib/python2.7/dist-packages/django/core/handlers/base.py", line 115, in get_response
[Tue Apr 22 10:05:17 2014] [error]     response = callback(request, *callback_args, **callback_kwargs)
[Tue Apr 22 10:05:17 2014] [error]   File "/usr/lib/python2.7/dist-packages/horizon/decorators.py", line 38, in dec
[Tue Apr 22 10:05:17 2014] [error]     return view_func(request, *args, **kwargs)
[Tue Apr 22 10:05:17 2014] [error]   File "/usr/lib/python2.7/dist-packages/horizon/decorators.py", line 86, in dec
[Tue Apr 22 10:05:17 2014] [error]     return view_func(request, *args, **kwargs)
[Tue Apr 22 10:05:17 2014] [error]   File "/usr/lib/python2.7/dist-packages/horizon/decorators.py", line 54, in dec
[Tue Apr 22 10:05:17 2014] [error]     return view_func(request, *args, **kwargs)
[Tue Apr 22 10:05:17 2014] [error]   File "/usr/lib/python2.7/dist-packages/horizon/decorators.py", line 38, in dec
[Tue Apr 22 10:05:17 2014] [error]     return view_func(request, *args, **kwargs)
[Tue Apr 22 10:05:17 2014] [error]   File "/usr/lib/python2.7/dist-packages/horizon/decorators.py", line 86, in dec
[Tue Apr 22 10:05:17 2014] [error]     return view_func(request, *args, **kwargs)
[Tue Apr 22 10:05:17 2014] [error]   File "/usr/lib/python2.7/dist-packages/django/views/generic/base.py", line 68, in view
[Tue Apr 22 10:05:17 2014] [error]     return self.dispatch(request, *args, **kwargs)
[Tue Apr 22 10:05:17 2014] [error]   File "/usr/lib/python2.7/dist-packages/django/views/generic/base.py", line 86, in dispatch
[Tue Apr 22 10:05:17 2014] [error]     return handler(request, *args, **kwargs)
[Tue Apr 22 10:05:17 2014] [error]   File "/usr/lib/python2.7/dist-packages/horizon/tables/views.py", line 155, in get
[Tue Apr 22 10:05:17 2014] [error]     handled = self.construct_tables()
[Tue Apr 22 10:05:17 2014] [error]   File "/usr/lib/python2.7/dist-packages/horizon/tables/views.py", line 146, in construct_tables
[Tue Apr 22 10:05:17 2014] [error]     handled = self.handle_table(table)
[Tue Apr 22 10:05:17 2014] [error]   File "/usr/lib/python2.7/dist-packages/horizon/tables/views.py", line 118, in handle_table
[Tue Apr 22 10:05:17 2014] [error]     data = self._get_data_dict()
[Tue Apr 22 10:05:17 2014] [error]   File "/usr/lib/python2.7/dist-packages/horizon/tables/views.py", line 182, in _get_data_dict
[Tue Apr 22 10:05:17 2014] [error]     self._data = {self.table_class._meta.name: self.get_data()}
[Tue Apr 22 10:05:17 2014] [error]   File "/usr/share/openstack-dashboard/openstack_dashboard/wsgi/../../openstack_dashboard/dashboards/admin/overview/views.py", line 59, in get_data
[Tue Apr 22 10:05:17 2014] [error]     data = super(GlobalOverview, self).get_data()
[Tue Apr 22 10:05:17 2014] [error]   File "/usr/share/openstack-dashboard/openstack_dashboard/wsgi/../../openstack_dashboard/usage/views.py", line 28, in get_data
[Tue Apr 22 10:05:17 2014] [error]     self.usage.summarize(*self.usage.get_date_range())
[Tue Apr 22 10:05:17 2014] [error]   File "/usr/share/openstack-dashboard/openstack_dashboard/wsgi/../../openstack_dashboard/usage/base.py", line 193, in summarize
[Tue Apr 22 10:05:17 2014] [error]     _('Unable to retrieve usage information.'))
[Tue Apr 22 10:05:17 2014] [error]   File "/usr/share/openstack-dashboard/openstack_dashboard/wsgi/../../openstack_dashboard/usage/base.py", line 190, in summarize
[Tue Apr 22 10:05:17 2014] [error]     self.usage_list = self.get_usage_list(start, end)
[Tue Apr 22 10:05:17 2014] [error]   File "/usr/share/openstack-dashboard/openstack_dashboard/wsgi/../../openstack_dashboard/usage/base.py", line 231, in get_usage_list
[Tue Apr 22 10:05:17 2014] [error]     return api.nova.usage_list(self.request, start, end)
[Tue Apr 22 10:05:17 2014] [error]   File "/usr/share/openstack-dashboard/openstack_dashboard/wsgi/../../openstack_dashboard/api/nova.py", line 605, in usage_list
[Tue Apr 22 10:05:17 2014] [error]     novaclient(request).usage.list(start, end, True)]
[Tue Apr 22 10:05:17 2014] [error]   File "/usr/lib/python2.7/dist-packages/novaclient/v1_1/usage.py", line 35, in list
[Tue Apr 22 10:05:17 2014] [error]     "tenant_usages")
[Tue Apr 22 10:05:17 2014] [error]   File "/usr/lib/python2.7/dist-packages/novaclient/base.py", line 61, in _list
[Tue Apr 22 10:05:17 2014] [error]     _resp, body = self.api.client.get(url)
[Tue Apr 22 10:05:17 2014] [error]   File "/usr/lib/python2.7/dist-packages/novaclient/client.py", line 229, in get
[Tue Apr 22 10:05:17 2014] [error]     return self._cs_request(url, 'GET', **kwargs)
[Tue Apr 22 10:05:17 2014] [error]   File "/usr/lib/python2.7/dist-packages/novaclient/client.py", line 213, in _cs_request
[Tue Apr 22 10:05:17 2014] [error]     **kwargs)
[Tue Apr 22 10:05:17 2014] [error]   File "/usr/lib/python2.7/dist-packages/novaclient/client.py", line 195, in _time_request
[Tue Apr 22 10:05:17 2014] [error]     resp, body = self.request(url, method, **kwargs)
[Tue Apr 22 10:05:17 2014] [error]   File "/usr/lib/python2.7/dist-packages/novaclient/client.py", line 166, in request
[Tue Apr 22 10:05:17 2014] [error]     **kwargs)
[Tue Apr 22 10:05:17 2014] [error]   File "/usr/lib/python2.7/dist-packages/requests/sessions.py", line 335, in request
[Tue Apr 22 10:05:17 2014] [error]     resp = self.send(prep, **send_kwargs)
[Tue Apr 22 10:05:17 2014] [error]   File "/usr/lib/python2.7/dist-packages/requests/sessions.py", line 438, in send
[Tue Apr 22 10:05:17 2014] [error]     r = adapter.send(request, **kwargs)
[Tue Apr 22 10:05:17 2014] [error]   File "/usr/lib/python2.7/dist-packages/requests/adapters.py", line 327, in send
[Tue Apr 22 10:05:17 2014] [error]     raise ConnectionError(e)
[Tue Apr 22 10:05:17 2014] [error] ConnectionError: HTTPConnectionPool(host='csi', port=8774): Max retries exceeded with url: /v2/e7dcfe9fe2f143d29e518e41a20553cf/os-simple-tenant-usage?start=2014-04-22T00:00:00&end=2014-04-22T23:59:59&detailed=1 (Caused by <class 'socket.error'>: [Errno 104] Connection reset by peer)
[Tue Apr 22 10:05:17 2014] [error] Error while checking action permissions.
[Tue Apr 22 10:05:17 2014] [error] Traceback (most recent call last):
[Tue Apr 22 10:05:17 2014] [error]   File "/usr/lib/python2.7/dist-packages/horizon/tables/base.py", line 1004, in _filter_action
[Tue Apr 22 10:05:17 2014] [error]     return action._allowed(request, datum) and row_matched
[Tue Apr 22 10:05:17 2014] [error]   File "/usr/lib/python2.7/dist-packages/horizon/tables/actions.py", line 543, in _allowed
[Tue Apr 22 10:05:17 2014] [error]     return super(BatchAction, self)._allowed(request, datum)
[Tue Apr 22 10:05:17 2014] [error]   File "/usr/lib/python2.7/dist-packages/horizon/tables/actions.py", line 90, in _allowed
[Tue Apr 22 10:05:17 2014] [error]     return self.allowed(request, datum)
[Tue Apr 22 10:05:17 2014] [error]   File "/usr/share/openstack-dashboard/openstack_dashboard/wsgi/../../openstack_dashboard/dashboards/project/instances/tables.py", line 127, in allowed
[Tue Apr 22 10:05:17 2014] [error]     request):
[Tue Apr 22 10:05:17 2014] [error]   File "/usr/lib/python2.7/dist-packages/horizon/utils/memoized.py", line 33, in __call__
[Tue Apr 22 10:05:17 2014] [error]     value = self.func(*args)
[Tue Apr 22 10:05:17 2014] [error]   File "/usr/share/openstack-dashboard/openstack_dashboard/wsgi/../../openstack_dashboard/api/nova.py", line 691, in extension_supported
[Tue Apr 22 10:05:17 2014] [error]     extensions = list_extensions(request)
[Tue Apr 22 10:05:17 2014] [error]   File "/usr/lib/python2.7/dist-packages/horizon/utils/memoized.py", line 33, in __call__
[Tue Apr 22 10:05:17 2014] [error]     value = self.func(*args)
[Tue Apr 22 10:05:17 2014] [error]   File "/usr/share/openstack-dashboard/openstack_dashboard/wsgi/../../openstack_dashboard/api/nova.py", line 681, in list_extensions
[Tue Apr 22 10:05:17 2014] [error]     return nova_list_extensions.ListExtManager(novaclient(request)).show_all()
[Tue Apr 22 10:05:17 2014] [error]   File "/usr/lib/python2.7/dist-packages/novaclient/v1_1/contrib/list_extensions.py", line 37, in show_all
[Tue Apr 22 10:05:17 2014] [error]     return self._list("/extensions", 'extensions')
[Tue Apr 22 10:05:17 2014] [error]   File "/usr/lib/python2.7/dist-packages/novaclient/base.py", line 61, in _list
[Tue Apr 22 10:05:17 2014] [error]     _resp, body = self.api.client.get(url)
[Tue Apr 22 10:05:17 2014] [error]   File "/usr/lib/python2.7/dist-packages/novaclient/client.py", line 229, in get
[Tue Apr 22 10:05:17 2014] [error]     return self._cs_request(url, 'GET', **kwargs)
[Tue Apr 22 10:05:17 2014] [error]   File "/usr/lib/python2.7/dist-packages/novaclient/client.py", line 213, in _cs_request
[Tue Apr 22 10:05:17 2014] [error]     **kwargs)
[Tue Apr 22 10:05:17 2014] [error]   File "/usr/lib/python2.7/dist-packages/novaclient/client.py", line 195, in _time_request
[Tue Apr 22 10:05:17 2014] [error]     resp, body = self.request(url, method, **kwargs)
[Tue Apr 22 10:05:17 2014] [error]   File "/usr/lib/python2.7/dist-packages/novaclient/client.py", line 166, in request
[Tue Apr 22 10:05:17 2014] [error]     **kwargs)
[Tue Apr 22 10:05:17 2014] [error]   File "/usr/lib/python2.7/dist-packages/requests/sessions.py", line 335, in request
[Tue Apr 22 10:05:17 2014] [error]     resp = self.send(prep, **send_kwargs)
[Tue Apr 22 10:05:17 2014] [error]   File "/usr/lib/python2.7/dist-packages/requests/sessions.py", line 438, in send
[Tue Apr 22 10:05:17 2014] [error]     r = adapter.send(request, **kwargs)
[Tue Apr 22 10:05:17 2014] [error]   File "/usr/lib/python2.7/dist-packages/requests/adapters.py", line 327, in send
[Tue Apr 22 10:05:17 2014] [error]     raise ConnectionError(e)
[Tue Apr 22 10:05:17 2014] [error] ConnectionError: HTTPConnectionPool(host='csi', port=8774): Max retries exceeded with url: /v2/e7dcfe9fe2f143d29e518e41a20553cf/extensions (Caused by <class 'socket.error'>: [Errno 111] Connection refused)
[Tue Apr 22 10:05:17 2014] [error] Error while checking action permissions.
[Tue Apr 22 10:05:17 2014] [error] Traceback (most recent call last):
[Tue Apr 22 10:05:17 2014] [error]   File "/usr/lib/python2.7/dist-packages/horizon/tables/base.py", line 1004, in _filter_action
[Tue Apr 22 10:05:17 2014] [error]     return action._allowed(request, datum) and row_matched
[Tue Apr 22 10:05:17 2014] [error]   File "/usr/lib/python2.7/dist-packages/horizon/tables/actions.py", line 543, in _allowed
[Tue Apr 22 10:05:17 2014] [error]     return super(BatchAction, self)._allowed(request, datum)
[Tue Apr 22 10:05:17 2014] [error]   File "/usr/lib/python2.7/dist-packages/horizon/tables/actions.py", line 90, in _allowed
[Tue Apr 22 10:05:17 2014] [error]     return self.allowed(request, datum)
[Tue Apr 22 10:05:17 2014] [error]   File "/usr/share/openstack-dashboard/openstack_dashboard/wsgi/../../openstack_dashboard/dashboards/project/instances/tables.py", line 159, in allowed
[Tue Apr 22 10:05:17 2014] [error]     request):
[Tue Apr 22 10:05:17 2014] [error]   File "/usr/lib/python2.7/dist-packages/horizon/utils/memoized.py", line 33, in __call__
[Tue Apr 22 10:05:17 2014] [error]     value = self.func(*args)
[Tue Apr 22 10:05:17 2014] [error]   File "/usr/share/openstack-dashboard/openstack_dashboard/wsgi/../../openstack_dashboard/api/nova.py", line 691, in extension_supported
[Tue Apr 22 10:05:17 2014] [error]     extensions = list_extensions(request)
[Tue Apr 22 10:05:17 2014] [error]   File "/usr/lib/python2.7/dist-packages/horizon/utils/memoized.py", line 33, in __call__
[Tue Apr 22 10:05:17 2014] [error]     value = self.func(*args)
[Tue Apr 22 10:05:17 2014] [error]   File "/usr/share/openstack-dashboard/openstack_dashboard/wsgi/../../openstack_dashboard/api/nova.py", line 681, in list_extensions
[Tue Apr 22 10:05:17 2014] [error]     return nova_list_extensions.ListExtManager(novaclient(request)).show_all()
[Tue Apr 22 10:05:17 2014] [error]   File "/usr/lib/python2.7/dist-packages/novaclient/v1_1/contrib/list_extensions.py", line 37, in show_all
[Tue Apr 22 10:05:17 2014] [error]     return self._list("/extensions", 'extensions')
[Tue Apr 22 10:05:17 2014] [error]   File "/usr/lib/python2.7/dist-packages/novaclient/base.py", line 61, in _list
[Tue Apr 22 10:05:17 2014] [error]     _resp, body = self.api.client.get(url)
[Tue Apr 22 10:05:17 2014] [error]   File "/usr/lib/python2.7/dist-packages/novaclient/client.py", line 229, in get
[Tue Apr 22 10:05:17 2014] [error]     return self._cs_request(url, 'GET', **kwargs)
[Tue Apr 22 10:05:17 2014] [error]   File "/usr/lib/python2.7/dist-packages/novaclient/client.py", line 213, in _cs_request
[Tue Apr 22 10:05:17 2014] [error]     **kwargs)
[Tue Apr 22 10:05:17 2014] [error]   File "/usr/lib/python2.7/dist-packages/novaclient/client.py", line 195, in _time_request
[Tue Apr 22 10:05:17 2014] [error]     resp, body = self.request(url, method, **kwargs)
[Tue Apr 22 10:05:17 2014] [error]   File "/usr/lib/python2.7/dist-packages/novaclient/client.py", line 166, in request
[Tue Apr 22 10:05:17 2014] [error]     **kwargs)
[Tue Apr 22 10:05:17 2014] [error]   File "/usr/lib/python2.7/dist-packages/requests/sessions.py", line 335, in request
[Tue Apr 22 10:05:17 2014] [error]     resp = self.send(prep, **send_kwargs)
[Tue Apr 22 10:05:17 2014] [error]   File "/usr/lib/python2.7/dist-packages/requests/sessions.py", line 438, in send
[Tue Apr 22 10:05:17 2014] [error]     r = adapter.send(request, **kwargs)
[Tue Apr 22 10:05:17 2014] [error]   File "/usr/lib/python2.7/dist-packages/requests/adapters.py", line 327, in send
[Tue Apr 22 10:05:17 2014] [error]     raise ConnectionError(e)
[Tue Apr 22 10:05:17 2014] [error] ConnectionError: HTTPConnectionPool(host='csi', port=8774): Max retries exceeded with url: /v2/e7dcfe9fe2f143d29e518e41a20553cf/extensions (Caused by <class 'socket.error'>: [Errno 111] Connection refused)
[Tue Apr 22 10:05:17 2014] [error] Error while checking action permissions.
[Tue Apr 22 10:05:17 2014] [error] Traceback (most recent call last):
[Tue Apr 22 10:05:17 2014] [error]   File "/usr/lib/python2.7/dist-packages/horizon/tables/base.py", line 1004, in _filter_action
[Tue Apr 22 10:05:17 2014] [error]     return action._allowed(request, datum) and row_matched
[Tue Apr 22 10:05:17 2014] [error]   File "/usr/lib/python2.7/dist-packages/horizon/tables/actions.py", line 543, in _allowed
[Tue Apr 22 10:05:17 2014] [error]     return super(BatchAction, self)._allowed(request, datum)
[Tue Apr 22 10:05:17 2014] [error]   File "/usr/lib/python2.7/dist-packages/horizon/tables/actions.py", line 90, in _allowed
[Tue Apr 22 10:05:17 2014] [error]     return self.allowed(request, datum)
[Tue Apr 22 10:05:17 2014] [error]   File "/usr/share/openstack-dashboard/openstack_dashboard/wsgi/../../openstack_dashboard/dashboards/project/instances/tables.py", line 127, in allowed
[Tue Apr 22 10:05:17 2014] [error]     request):
[Tue Apr 22 10:05:17 2014] [error]   File "/usr/lib/python2.7/dist-packages/horizon/utils/memoized.py", line 33, in __call__
[Tue Apr 22 10:05:17 2014] [error]     value = self.func(*args)
[Tue Apr 22 10:05:17 2014] [error]   File "/usr/share/openstack-dashboard/openstack_dashboard/wsgi/../../openstack_dashboard/api/nova.py", line 691, in extension_supported
[Tue Apr 22 10:05:17 2014] [error]     extensions = list_extensions(request)
[Tue Apr 22 10:05:17 2014] [error]   File "/usr/lib/python2.7/dist-packages/horizon/utils/memoized.py", line 33, in __call__
[Tue Apr 22 10:05:17 2014] [error]     value = self.func(*args)
[Tue Apr 22 10:05:17 2014] [error]   File "/usr/share/openstack-dashboard/openstack_dashboard/wsgi/../../openstack_dashboard/api/nova.py", line 681, in list_extensions
[Tue Apr 22 10:05:17 2014] [error]     return nova_list_extensions.ListExtManager(novaclient(request)).show_all()
[Tue Apr 22 10:05:17 2014] [error]   File "/usr/lib/python2.7/dist-packages/novaclient/v1_1/contrib/list_extensions.py", line 37, in show_all
[Tue Apr 22 10:05:17 2014] [error]     return self._list("/extensions", 'extensions')
[Tue Apr 22 10:05:17 2014] [error]   File "/usr/lib/python2.7/dist-packages/novaclient/base.py", line 61, in _list
[Tue Apr 22 10:05:17 2014] [error]     _resp, body = self.api.client.get(url)
[Tue Apr 22 10:05:17 2014] [error]   File "/usr/lib/python2.7/dist-packages/novaclient/client.py", line 229, in get
[Tue Apr 22 10:05:17 2014] [error]     return self._cs_request(url, 'GET', **kwargs)
[Tue Apr 22 10:05:17 2014] [error]   File "/usr/lib/python2.7/dist-packages/novaclient/client.py", line 213, in _cs_request
[Tue Apr 22 10:05:17 2014] [error]     **kwargs)
[Tue Apr 22 10:05:17 2014] [error]   File "/usr/lib/python2.7/dist-packages/novaclient/client.py", line 195, in _time_request
[Tue Apr 22 10:05:17 2014] [error]     resp, body = self.request(url, method, **kwargs)
[Tue Apr 22 10:05:17 2014] [error]   File "/usr/lib/python2.7/dist-packages/novaclient/client.py", line 166, in request
[Tue Apr 22 10:05:17 2014] [error]     **kwargs)
[Tue Apr 22 10:05:17 2014] [error]   File "/usr/lib/python2.7/dist-packages/requests/sessions.py", line 335, in request
[Tue Apr 22 10:05:17 2014] [error]     resp = self.send(prep, **send_kwargs)
[Tue Apr 22 10:05:17 2014] [error]   File "/usr/lib/python2.7/dist-packages/requests/sessions.py", line 438, in send
[Tue Apr 22 10:05:17 2014] [error]     r = adapter.send(request, **kwargs)
[Tue Apr 22 10:05:17 2014] [error]   File "/usr/lib/python2.7/dist-packages/requests/adapters.py", line 327, in send
[Tue Apr 22 10:05:17 2014] [error]     raise ConnectionError(e)
[Tue Apr 22 10:05:17 2014] [error] ConnectionError: HTTPConnectionPool(host='csi', port=8774): Max retries exceeded with url: /v2/e7dcfe9fe2f143d29e518e41a20553cf/extensions (Caused by <class 'socket.error'>: [Errno 111] Connection refused)
[Tue Apr 22 10:05:17 2014] [error] Error while checking action permissions.
[Tue Apr 22 10:05:17 2014] [error] Traceback (most recent call last):
[Tue Apr 22 10:05:17 2014] [error]   File "/usr/lib/python2.7/dist-packages/horizon/tables/base.py", line 1004, in _filter_action
[Tue Apr 22 10:05:17 2014] [error]     return action._allowed(request, datum) and row_matched
[Tue Apr 22 10:05:17 2014] [error]   File "/usr/lib/python2.7/dist-packages/horizon/tables/actions.py", line 543, in _allowed
[Tue Apr 22 10:05:17 2014] [error]     return super(BatchAction, self)._allowed(request, datum)
[Tue Apr 22 10:05:17 2014] [error]   File "/usr/lib/python2.7/dist-packages/horizon/tables/actions.py", line 90, in _allowed
[Tue Apr 22 10:05:17 2014] [error]     return self.allowed(request, datum)
[Tue Apr 22 10:05:17 2014] [error]   File "/usr/share/openstack-dashboard/openstack_dashboard/wsgi/../../openstack_dashboard/dashboards/project/instances/tables.py", line 159, in allowed
[Tue Apr 22 10:05:17 2014] [error]     request):
[Tue Apr 22 10:05:17 2014] [error]   File "/usr/lib/python2.7/dist-packages/horizon/utils/memoized.py", line 33, in __call__
[Tue Apr 22 10:05:17 2014] [error]     value = self.func(*args)
[Tue Apr 22 10:05:17 2014] [error]   File "/usr/share/openstack-dashboard/openstack_dashboard/wsgi/../../openstack_dashboard/api/nova.py", line 691, in extension_supported
[Tue Apr 22 10:05:17 2014] [error]     extensions = list_extensions(request)
[Tue Apr 22 10:05:17 2014] [error]   File "/usr/lib/python2.7/dist-packages/horizon/utils/memoized.py", line 33, in __call__
[Tue Apr 22 10:05:17 2014] [error]     value = self.func(*args)
[Tue Apr 22 10:05:17 2014] [error]   File "/usr/share/openstack-dashboard/openstack_dashboard/wsgi/../../openstack_dashboard/api/nova.py", line 681, in list_extensions
[Tue Apr 22 10:05:17 2014] [error]     return nova_list_extensions.ListExtManager(novaclient(request)).show_all()
[Tue Apr 22 10:05:17 2014] [error]   File "/usr/lib/python2.7/dist-packages/novaclient/v1_1/contrib/list_extensions.py", line 37, in show_all
[Tue Apr 22 10:05:17 2014] [error]     return self._list("/extensions", 'extensions')
[Tue Apr 22 10:05:17 2014] [error]   File "/usr/lib/python2.7/dist-packages/novaclient/base.py", line 61, in _list
[Tue Apr 22 10:05:17 2014] [error]     _resp, body = self.api.client.get(url)
[Tue Apr 22 10:05:17 2014] [error]   File "/usr/lib/python2.7/dist-packages/novaclient/client.py", line 229, in get
[Tue Apr 22 10:05:17 2014] [error]     return self._cs_request(url, 'GET', **kwargs)
[Tue Apr 22 10:05:17 2014] [error]   File "/usr/lib/python2.7/dist-packages/novaclient/client.py", line 213, in _cs_request
[Tue Apr 22 10:05:17 2014] [error]     **kwargs)
[Tue Apr 22 10:05:17 2014] [error]   File "/usr/lib/python2.7/dist-packages/novaclient/client.py", line 195, in _time_request
[Tue Apr 22 10:05:17 2014] [error]     resp, body = self.request(url, method, **kwargs)
[Tue Apr 22 10:05:17 2014] [error]   File "/usr/lib/python2.7/dist-packages/novaclient/client.py", line 166, in request
[Tue Apr 22 10:05:17 2014] [error]     **kwargs)
[Tue Apr 22 10:05:17 2014] [error]   File "/usr/lib/python2.7/dist-packages/requests/sessions.py", line 335, in request
[Tue Apr 22 10:05:17 2014] [error]     resp = self.send(prep, **send_kwargs)
[Tue Apr 22 10:05:17 2014] [error]   File "/usr/lib/python2.7/dist-packages/requests/sessions.py", line 438, in send
[Tue Apr 22 10:05:17 2014] [error]     r = adapter.send(request, **kwargs)
[Tue Apr 22 10:05:17 2014] [error]   File "/usr/lib/python2.7/dist-packages/requests/adapters.py", line 327, in send
[Tue Apr 22 10:05:17 2014] [error]     raise ConnectionError(e)
[Tue Apr 22 10:05:17 2014] [error] ConnectionError: HTTPConnectionPool(host='csi', port=8774): Max retries exceeded with url: /v2/e7dcfe9fe2f143d29e518e41a20553cf/extensions (Caused by <class 'socket.error'>: [Errno 111] Connection refused)
[Tue Apr 22 10:05:17 2014] [error] Failed to retrieve quota information
[Tue Apr 22 10:05:17 2014] [error] Traceback (most recent call last):
[Tue Apr 22 10:05:17 2014] [error]   File "/usr/share/openstack-dashboard/openstack_dashboard/wsgi/../../openstack_dashboard/dashboards/project/instances/tables.py", line 189, in allowed
[Tue Apr 22 10:05:17 2014] [error]     limits = api.nova.tenant_absolute_limits(request, reserved=True)
[Tue Apr 22 10:05:17 2014] [error]   File "/usr/share/openstack-dashboard/openstack_dashboard/wsgi/../../openstack_dashboard/api/nova.py", line 652, in tenant_absolute_limits
[Tue Apr 22 10:05:17 2014] [error]     limits = novaclient(request).limits.get(reserved=reserved).absolute
[Tue Apr 22 10:05:17 2014] [error]   File "/usr/lib/python2.7/dist-packages/novaclient/v1_1/limits.py", line 87, in get
[Tue Apr 22 10:05:17 2014] [error]     return self._get("/limits%s" % query_string, "limits")
[Tue Apr 22 10:05:17 2014] [error]   File "/usr/lib/python2.7/dist-packages/novaclient/base.py", line 140, in _get
[Tue Apr 22 10:05:17 2014] [error]     _resp, body = self.api.client.get(url)
[Tue Apr 22 10:05:17 2014] [error]   File "/usr/lib/python2.7/dist-packages/novaclient/client.py", line 229, in get
[Tue Apr 22 10:05:17 2014] [error]     return self._cs_request(url, 'GET', **kwargs)
[Tue Apr 22 10:05:17 2014] [error]   File "/usr/lib/python2.7/dist-packages/novaclient/client.py", line 213, in _cs_request
[Tue Apr 22 10:05:17 2014] [error]     **kwargs)
[Tue Apr 22 10:05:17 2014] [error]   File "/usr/lib/python2.7/dist-packages/novaclient/client.py", line 195, in _time_request
[Tue Apr 22 10:05:17 2014] [error]     resp, body = self.request(url, method, **kwargs)
[Tue Apr 22 10:05:17 2014] [error]   File "/usr/lib/python2.7/dist-packages/novaclient/client.py", line 166, in request
[Tue Apr 22 10:05:17 2014] [error]     **kwargs)
[Tue Apr 22 10:05:17 2014] [error]   File "/usr/lib/python2.7/dist-packages/requests/sessions.py", line 335, in request
[Tue Apr 22 10:05:17 2014] [error]     resp = self.send(prep, **send_kwargs)
[Tue Apr 22 10:05:17 2014] [error]   File "/usr/lib/python2.7/dist-packages/requests/sessions.py", line 438, in send
[Tue Apr 22 10:05:17 2014] [error]     r = adapter.send(request, **kwargs)
[Tue Apr 22 10:05:17 2014] [error]   File "/usr/lib/python2.7/dist-packages/requests/adapters.py", line 327, in send
[Tue Apr 22 10:05:17 2014] [error]     raise ConnectionError(e)
[Tue Apr 22 10:05:17 2014] [error] ConnectionError: HTTPConnectionPool(host='csi', port=8774): Max retries exceeded with url: /v2/e7dcfe9fe2f143d29e518e41a20553cf/limits?reserved=1 (Caused by <class 'socket.error'>: [Errno 111] Connection refused)
[Tue Apr 22 10:14:01 2014] [error] Soft Rebooted Instance: "iptest"
[Tue Apr 22 10:14:08 2014] [error] Soft Rebooted Instance: "sshtest4"
[Tue Apr 22 10:23:13 2014] [error] Scheduled termination of Instance: "memtest2-ef0bbed6-4d99-4290-b2ca-b32905b9e6a4"
[Tue Apr 22 10:25:23 2014] [error] Scheduled termination of Instance: "test5"
[Tue Apr 22 10:25:31 2014] [error] Scheduled termination of Instance: "memtest3"
[Tue Apr 22 10:26:29 2014] [error] Scheduled termination of Instance: "memdgsdg"
[Tue Apr 22 10:27:44 2014] [error] [client 192.168.0.4] File does not exist: /var/www/auth
[Tue Apr 22 10:27:44 2014] [error] [client 192.168.0.4] File does not exist: /var/www/favicon.ico
[Tue Apr 22 10:27:44 2014] [error] [client 192.168.0.4] File does not exist: /var/www/favicon.ico
[Tue Apr 22 10:51:07 2014] [error] Scheduled termination of Instance: "memtest2-699ed187-e91a-4674-ad23-be4f13a84d10"
[Tue Apr 22 10:52:19 2014] [error] Scheduled termination of Instance: "teste435346"
[Tue Apr 22 10:52:47 2014] [error] Logging out user "admin".
[Tue Apr 22 10:52:58 2014] [error] Login successful for user "macos".
[Tue Apr 22 10:53:31 2014] [error] Scheduled termination of Instance: "gsdg5"
[Tue Apr 22 10:53:39 2014] [error] Logging out user "macos".
[Tue Apr 22 10:53:39 2014] [error] Could not delete token
[Tue Apr 22 10:53:48 2014] [error] Login successful for user "admin".
[Tue Apr 22 11:05:20 2014] [notice] caught SIGTERM, shutting down
[Tue Apr 22 11:06:29 2014] [warn] mod_wsgi: Compiled for Python/2.7.2+.
[Tue Apr 22 11:06:30 2014] [warn] mod_wsgi: Runtime using Python/2.7.3.
[Tue Apr 22 11:06:30 2014] [notice] Apache/2.2.22 (Ubuntu) mod_wsgi/3.3 Python/2.7.3 configured -- resuming normal operations
